[2020-05-05 23:05:24,933: INFO/MainProcess] Connected to redis://localhost:6379/0
[2020-05-05 23:05:24,941: INFO/MainProcess] mingle: searching for neighbors
[2020-05-05 23:05:25,956: WARNING/MainProcess] /usr/local/lib/python3.6/site-packages/celery/app/control.py:54: DuplicateNodenameWarning: Received multiple replies from node name: celery@iZwz9aplpg9q5kwob3xhkiZ.
Please make sure you give each node a unique nodename using
the celery worker `-n` option.
  pluralize(len(dupes), 'name'), ', '.join(sorted(dupes)),
[2020-05-05 23:05:25,956: INFO/MainProcess] mingle: all alone
[2020-05-05 23:05:25,963: INFO/MainProcess] celery@iZwz9aplpg9q5kwob3xhkiZ ready.
[2020-05-05 23:26:00,413: INFO/MainProcess] Connected to redis://localhost:6379/0
[2020-05-05 23:26:00,422: INFO/MainProcess] mingle: searching for neighbors
[2020-05-05 23:26:01,439: WARNING/MainProcess] /usr/local/lib/python3.6/site-packages/celery/app/control.py:54: DuplicateNodenameWarning: Received multiple replies from node name: celery@iZwz9aplpg9q5kwob3xhkiZ.
Please make sure you give each node a unique nodename using
the celery worker `-n` option.
  pluralize(len(dupes), 'name'), ', '.join(sorted(dupes)),
[2020-05-05 23:26:01,439: INFO/MainProcess] mingle: all alone
[2020-05-05 23:26:01,446: INFO/MainProcess] celery@iZwz9aplpg9q5kwob3xhkiZ ready.
[2020-05-07 06:08:04,470: ERROR/MainProcess] Failed to submit message: "Unable to reach APM Server: ('Connection aborted.', RemoteDisconnected('Remote end closed connection without response',)) (url: http://127.0.0.1:8200/intake/v2/events)"
Traceback (most recent call last):
  File "/usr/local/lib/python3.6/site-packages/urllib3/connectionpool.py", line 672, in urlopen
    chunked=chunked,
  File "/usr/local/lib/python3.6/site-packages/urllib3/connectionpool.py", line 421, in _make_request
    six.raise_from(e, None)
  File "<string>", line 3, in raise_from
  File "/usr/local/lib/python3.6/site-packages/urllib3/connectionpool.py", line 416, in _make_request
    httplib_response = conn.getresponse()
  File "/usr/lib64/python3.6/http/client.py", line 1346, in getresponse
    response.begin()
  File "/usr/lib64/python3.6/http/client.py", line 307, in begin
    version, status, reason = self._read_status()
  File "/usr/lib64/python3.6/http/client.py", line 276, in _read_status
    raise RemoteDisconnected("Remote end closed connection without"
http.client.RemoteDisconnected: Remote end closed connection without response

During handling of the above exception, another exception occurred:

Traceback (most recent call last):
  File "/usr/local/lib64/python3.6/site-packages/elasticapm/transport/http.py", line 82, in send
    "POST", url, body=data, headers=headers, timeout=self._timeout, preload_content=False
  File "/usr/local/lib/python3.6/site-packages/urllib3/poolmanager.py", line 330, in urlopen
    response = conn.urlopen(method, u.request_uri, **kw)
  File "/usr/local/lib64/python3.6/site-packages/elasticapm/instrumentation/packages/base.py", line 205, in call_if_sampling
    return wrapped(*args, **kwargs)
  File "/usr/local/lib/python3.6/site-packages/urllib3/connectionpool.py", line 720, in urlopen
    method, url, error=e, _pool=self, _stacktrace=sys.exc_info()[2]
  File "/usr/local/lib/python3.6/site-packages/urllib3/util/retry.py", line 400, in increment
    raise six.reraise(type(error), error, _stacktrace)
  File "/usr/local/lib/python3.6/site-packages/urllib3/packages/six.py", line 734, in reraise
    raise value.with_traceback(tb)
  File "/usr/local/lib/python3.6/site-packages/urllib3/connectionpool.py", line 672, in urlopen
    chunked=chunked,
  File "/usr/local/lib/python3.6/site-packages/urllib3/connectionpool.py", line 421, in _make_request
    six.raise_from(e, None)
  File "<string>", line 3, in raise_from
  File "/usr/local/lib/python3.6/site-packages/urllib3/connectionpool.py", line 416, in _make_request
    httplib_response = conn.getresponse()
  File "/usr/lib64/python3.6/http/client.py", line 1346, in getresponse
    response.begin()
  File "/usr/lib64/python3.6/http/client.py", line 307, in begin
    version, status, reason = self._read_status()
  File "/usr/lib64/python3.6/http/client.py", line 276, in _read_status
    raise RemoteDisconnected("Remote end closed connection without"
urllib3.exceptions.ProtocolError: ('Connection aborted.', RemoteDisconnected('Remote end closed connection without response',))

During handling of the above exception, another exception occurred:

Traceback (most recent call last):
  File "/usr/local/lib64/python3.6/site-packages/elasticapm/transport/base.py", line 224, in _flush
    self.send(data)
  File "/usr/local/lib64/python3.6/site-packages/elasticapm/transport/http.py", line 95, in send
    raise TransportException(message, data, print_trace=print_trace)
elasticapm.transport.base.TransportException: Unable to reach APM Server: ('Connection aborted.', RemoteDisconnected('Remote end closed connection without response',)) (url: http://127.0.0.1:8200/intake/v2/events)
[2020-05-07 14:25:09,751: WARNING/MainProcess] Retrying (Retry(total=2, connect=None, read=None, redirect=None, status=None)) after connection broken by 'NewConnectionError('<urllib3.connection.HTTPConnection object at 0x7f48d779f588>: Failed to establish a new connection: [Errno 111] Connection refused',)': /intake/v2/events
[2020-05-07 14:25:09,752: WARNING/MainProcess] Retrying (Retry(total=1, connect=None, read=None, redirect=None, status=None)) after connection broken by 'NewConnectionError('<urllib3.connection.HTTPConnection object at 0x7f48d7796240>: Failed to establish a new connection: [Errno 111] Connection refused',)': /intake/v2/events
[2020-05-07 14:25:09,753: WARNING/MainProcess] Retrying (Retry(total=0, connect=None, read=None, redirect=None, status=None)) after connection broken by 'NewConnectionError('<urllib3.connection.HTTPConnection object at 0x7f48d7796470>: Failed to establish a new connection: [Errno 111] Connection refused',)': /intake/v2/events
[2020-05-07 14:25:09,754: ERROR/MainProcess] Failed to submit message: 'Connection to APM Server timed out (url: http://127.0.0.1:8200/intake/v2/events, timeout: 5 seconds)'
[2020-05-07 14:25:39,733: WARNING/MainProcess] Retrying (Retry(total=2, connect=None, read=None, redirect=None, status=None)) after connection broken by 'NewConnectionError('<urllib3.connection.HTTPConnection object at 0x7f48d779f470>: Failed to establish a new connection: [Errno 111] Connection refused',)': /intake/v2/events
[2020-05-07 14:25:39,734: WARNING/MainProcess] Retrying (Retry(total=1, connect=None, read=None, redirect=None, status=None)) after connection broken by 'NewConnectionError('<urllib3.connection.HTTPConnection object at 0x7f48d7792be0>: Failed to establish a new connection: [Errno 111] Connection refused',)': /intake/v2/events
[2020-05-07 14:25:39,735: WARNING/MainProcess] Retrying (Retry(total=0, connect=None, read=None, redirect=None, status=None)) after connection broken by 'NewConnectionError('<urllib3.connection.HTTPConnection object at 0x7f48d7792fd0>: Failed to establish a new connection: [Errno 111] Connection refused',)': /intake/v2/events
[2020-05-07 14:25:39,736: ERROR/MainProcess] Failed to submit message: 'Connection to APM Server timed out (url: http://127.0.0.1:8200/intake/v2/events, timeout: 5 seconds)'
[2020-05-07 15:11:33,789: WARNING/MainProcess] Retrying (Retry(total=2, connect=None, read=None, redirect=None, status=None)) after connection broken by 'NewConnectionError('<urllib3.connection.HTTPConnection object at 0x7f48d76c77b8>: Failed to establish a new connection: [Errno 111] Connection refused',)': /intake/v2/events
[2020-05-07 15:11:33,790: WARNING/MainProcess] Retrying (Retry(total=1, connect=None, read=None, redirect=None, status=None)) after connection broken by 'NewConnectionError('<urllib3.connection.HTTPConnection object at 0x7f48d779f5f8>: Failed to establish a new connection: [Errno 111] Connection refused',)': /intake/v2/events
[2020-05-07 15:11:33,791: WARNING/MainProcess] Retrying (Retry(total=0, connect=None, read=None, redirect=None, status=None)) after connection broken by 'NewConnectionError('<urllib3.connection.HTTPConnection object at 0x7f48d779f630>: Failed to establish a new connection: [Errno 111] Connection refused',)': /intake/v2/events
[2020-05-07 15:11:33,791: ERROR/MainProcess] Failed to submit message: 'Connection to APM Server timed out (url: http://127.0.0.1:8200/intake/v2/events, timeout: 5 seconds)'
[2020-05-07 15:12:04,745: WARNING/MainProcess] Retrying (Retry(total=2, connect=None, read=None, redirect=None, status=None)) after connection broken by 'NewConnectionError('<urllib3.connection.HTTPConnection object at 0x7f48d779f588>: Failed to establish a new connection: [Errno 111] Connection refused',)': /intake/v2/events
[2020-05-07 15:12:04,746: WARNING/MainProcess] Retrying (Retry(total=1, connect=None, read=None, redirect=None, status=None)) after connection broken by 'NewConnectionError('<urllib3.connection.HTTPConnection object at 0x7f48d76c70b8>: Failed to establish a new connection: [Errno 111] Connection refused',)': /intake/v2/events
[2020-05-07 15:12:04,746: WARNING/MainProcess] Retrying (Retry(total=0, connect=None, read=None, redirect=None, status=None)) after connection broken by 'NewConnectionError('<urllib3.connection.HTTPConnection object at 0x7f48d76c7e48>: Failed to establish a new connection: [Errno 111] Connection refused',)': /intake/v2/events
[2020-05-07 15:12:04,746: ERROR/MainProcess] Failed to submit message: 'Connection to APM Server timed out (url: http://127.0.0.1:8200/intake/v2/events, timeout: 5 seconds)'
[2020-05-07 20:06:00,859: WARNING/MainProcess] Retrying (Retry(total=2, connect=None, read=None, redirect=None, status=None)) after connection broken by 'NewConnectionError('<urllib3.connection.HTTPConnection object at 0x7f48d76c7198>: Failed to establish a new connection: [Errno 111] Connection refused',)': /config/v1/agents
[2020-05-07 20:06:00,859: WARNING/MainProcess] Retrying (Retry(total=1, connect=None, read=None, redirect=None, status=None)) after connection broken by 'NewConnectionError('<urllib3.connection.HTTPConnection object at 0x7f48d76c7f28>: Failed to establish a new connection: [Errno 111] Connection refused',)': /config/v1/agents
[2020-05-07 20:06:00,859: WARNING/MainProcess] Retrying (Retry(total=0, connect=None, read=None, redirect=None, status=None)) after connection broken by 'NewConnectionError('<urllib3.connection.HTTPConnection object at 0x7f48d76c7390>: Failed to establish a new connection: [Errno 111] Connection refused',)': /config/v1/agents
[2020-05-07 20:06:03,559: WARNING/MainProcess] Retrying (Retry(total=2, connect=None, read=None, redirect=None, status=None)) after connection broken by 'NewConnectionError('<urllib3.connection.HTTPConnection object at 0x7f48d76c7b00>: Failed to establish a new connection: [Errno 111] Connection refused',)': /intake/v2/events
[2020-05-07 20:06:03,559: WARNING/MainProcess] Retrying (Retry(total=1, connect=None, read=None, redirect=None, status=None)) after connection broken by 'NewConnectionError('<urllib3.connection.HTTPConnection object at 0x7f48d76c7588>: Failed to establish a new connection: [Errno 111] Connection refused',)': /intake/v2/events
[2020-05-07 20:06:03,559: WARNING/MainProcess] Retrying (Retry(total=0, connect=None, read=None, redirect=None, status=None)) after connection broken by 'NewConnectionError('<urllib3.connection.HTTPConnection object at 0x7f48d779f4a8>: Failed to establish a new connection: [Errno 111] Connection refused',)': /intake/v2/events
[2020-05-07 20:06:03,560: ERROR/MainProcess] Failed to submit message: 'Connection to APM Server timed out (url: http://127.0.0.1:8200/intake/v2/events, timeout: 5 seconds)'
[2020-05-07 20:06:34,294: WARNING/MainProcess] Retrying (Retry(total=2, connect=None, read=None, redirect=None, status=None)) after connection broken by 'NewConnectionError('<urllib3.connection.HTTPConnection object at 0x7f48d76c7f60>: Failed to establish a new connection: [Errno 111] Connection refused',)': /intake/v2/events
[2020-05-07 20:06:34,295: WARNING/MainProcess] Retrying (Retry(total=1, connect=None, read=None, redirect=None, status=None)) after connection broken by 'NewConnectionError('<urllib3.connection.HTTPConnection object at 0x7f48d76c7908>: Failed to establish a new connection: [Errno 111] Connection refused',)': /intake/v2/events
[2020-05-07 20:06:34,295: WARNING/MainProcess] Retrying (Retry(total=0, connect=None, read=None, redirect=None, status=None)) after connection broken by 'NewConnectionError('<urllib3.connection.HTTPConnection object at 0x7f48d76c70f0>: Failed to establish a new connection: [Errno 111] Connection refused',)': /intake/v2/events
[2020-05-07 20:06:34,295: ERROR/MainProcess] Failed to submit message: 'Connection to APM Server timed out (url: http://127.0.0.1:8200/intake/v2/events, timeout: 5 seconds)'
[2020-05-07 20:07:04,568: WARNING/MainProcess] Retrying (Retry(total=2, connect=None, read=None, redirect=None, status=None)) after connection broken by 'NewConnectionError('<urllib3.connection.HTTPConnection object at 0x7f48d77960f0>: Failed to establish a new connection: [Errno 111] Connection refused',)': /intake/v2/events
[2020-05-07 20:07:04,569: WARNING/MainProcess] Retrying (Retry(total=1, connect=None, read=None, redirect=None, status=None)) after connection broken by 'NewConnectionError('<urllib3.connection.HTTPConnection object at 0x7f48d77963c8>: Failed to establish a new connection: [Errno 111] Connection refused',)': /intake/v2/events
[2020-05-07 20:07:04,569: WARNING/MainProcess] Retrying (Retry(total=0, connect=None, read=None, redirect=None, status=None)) after connection broken by 'NewConnectionError('<urllib3.connection.HTTPConnection object at 0x7f48d7796358>: Failed to establish a new connection: [Errno 111] Connection refused',)': /intake/v2/events
[2020-05-07 20:07:04,569: ERROR/MainProcess] Failed to submit message: 'Connection to APM Server timed out (url: http://127.0.0.1:8200/intake/v2/events, timeout: 5 seconds)'
[2020-05-07 20:07:36,222: WARNING/MainProcess] Retrying (Retry(total=2, connect=None, read=None, redirect=None, status=None)) after connection broken by 'NewConnectionError('<urllib3.connection.HTTPConnection object at 0x7f48d7796470>: Failed to establish a new connection: [Errno 111] Connection refused',)': /intake/v2/events
[2020-05-07 20:07:36,222: WARNING/MainProcess] Retrying (Retry(total=1, connect=None, read=None, redirect=None, status=None)) after connection broken by 'NewConnectionError('<urllib3.connection.HTTPConnection object at 0x7f48d76c7080>: Failed to establish a new connection: [Errno 111] Connection refused',)': /intake/v2/events
[2020-05-07 20:07:36,222: WARNING/MainProcess] Retrying (Retry(total=0, connect=None, read=None, redirect=None, status=None)) after connection broken by 'NewConnectionError('<urllib3.connection.HTTPConnection object at 0x7f48d76c75c0>: Failed to establish a new connection: [Errno 111] Connection refused',)': /intake/v2/events
[2020-05-07 20:07:36,223: ERROR/MainProcess] Failed to submit message: 'Connection to APM Server timed out (url: http://127.0.0.1:8200/intake/v2/events, timeout: 5 seconds)'
[2020-05-07 20:08:05,746: WARNING/MainProcess] Retrying (Retry(total=2, connect=None, read=None, redirect=None, status=None)) after connection broken by 'NewConnectionError('<urllib3.connection.HTTPConnection object at 0x7f48d76c70b8>: Failed to establish a new connection: [Errno 111] Connection refused',)': /intake/v2/events
[2020-05-07 20:08:05,746: WARNING/MainProcess] Retrying (Retry(total=1, connect=None, read=None, redirect=None, status=None)) after connection broken by 'NewConnectionError('<urllib3.connection.HTTPConnection object at 0x7f48d76c7f28>: Failed to establish a new connection: [Errno 111] Connection refused',)': /intake/v2/events
[2020-05-07 20:08:05,747: WARNING/MainProcess] Retrying (Retry(total=0, connect=None, read=None, redirect=None, status=None)) after connection broken by 'NewConnectionError('<urllib3.connection.HTTPConnection object at 0x7f48d76c7898>: Failed to establish a new connection: [Errno 111] Connection refused',)': /intake/v2/events
[2020-05-07 20:08:05,747: ERROR/MainProcess] Failed to submit message: 'Connection to APM Server timed out (url: http://127.0.0.1:8200/intake/v2/events, timeout: 5 seconds)'
[2020-05-07 20:08:37,149: WARNING/MainProcess] Retrying (Retry(total=2, connect=None, read=None, redirect=None, status=None)) after connection broken by 'NewConnectionError('<urllib3.connection.HTTPConnection object at 0x7f48d7796198>: Failed to establish a new connection: [Errno 111] Connection refused',)': /intake/v2/events
[2020-05-07 20:08:37,149: WARNING/MainProcess] Retrying (Retry(total=1, connect=None, read=None, redirect=None, status=None)) after connection broken by 'NewConnectionError('<urllib3.connection.HTTPConnection object at 0x7f48d7796358>: Failed to establish a new connection: [Errno 111] Connection refused',)': /intake/v2/events
[2020-05-07 20:08:37,150: WARNING/MainProcess] Retrying (Retry(total=0, connect=None, read=None, redirect=None, status=None)) after connection broken by 'NewConnectionError('<urllib3.connection.HTTPConnection object at 0x7f48d77964e0>: Failed to establish a new connection: [Errno 111] Connection refused',)': /intake/v2/events
[2020-05-07 20:08:37,150: ERROR/MainProcess] Failed to submit message: 'Connection to APM Server timed out (url: http://127.0.0.1:8200/intake/v2/events, timeout: 5 seconds)'
[2020-05-07 21:18:04,618: WARNING/MainProcess] Retrying (Retry(total=2, connect=None, read=None, redirect=None, status=None)) after connection broken by 'NewConnectionError('<urllib3.connection.HTTPConnection object at 0x7f48d76dc710>: Failed to establish a new connection: [Errno 111] Connection refused',)': /intake/v2/events
[2020-05-07 21:18:04,619: WARNING/MainProcess] Retrying (Retry(total=1, connect=None, read=None, redirect=None, status=None)) after connection broken by 'NewConnectionError('<urllib3.connection.HTTPConnection object at 0x7f48d76dc7f0>: Failed to establish a new connection: [Errno 111] Connection refused',)': /intake/v2/events
[2020-05-07 21:18:04,619: WARNING/MainProcess] Retrying (Retry(total=0, connect=None, read=None, redirect=None, status=None)) after connection broken by 'NewConnectionError('<urllib3.connection.HTTPConnection object at 0x7f48d76dc668>: Failed to establish a new connection: [Errno 111] Connection refused',)': /intake/v2/events
[2020-05-07 21:18:04,619: ERROR/MainProcess] Failed to submit message: 'Connection to APM Server timed out (url: http://127.0.0.1:8200/intake/v2/events, timeout: 5 seconds)'
[2020-05-07 21:18:34,145: WARNING/MainProcess] Retrying (Retry(total=2, connect=None, read=None, redirect=None, status=None)) after connection broken by 'NewConnectionError('<urllib3.connection.HTTPConnection object at 0x7f48d76dce48>: Failed to establish a new connection: [Errno 111] Connection refused',)': /intake/v2/events
[2020-05-07 21:18:34,146: WARNING/MainProcess] Retrying (Retry(total=1, connect=None, read=None, redirect=None, status=None)) after connection broken by 'NewConnectionError('<urllib3.connection.HTTPConnection object at 0x7f48d76dc160>: Failed to establish a new connection: [Errno 111] Connection refused',)': /intake/v2/events
[2020-05-07 21:18:34,146: WARNING/MainProcess] Retrying (Retry(total=0, connect=None, read=None, redirect=None, status=None)) after connection broken by 'NewConnectionError('<urllib3.connection.HTTPConnection object at 0x7f48d76dc5c0>: Failed to establish a new connection: [Errno 111] Connection refused',)': /intake/v2/events
[2020-05-07 21:18:34,147: ERROR/MainProcess] Failed to submit message: 'Connection to APM Server timed out (url: http://127.0.0.1:8200/intake/v2/events, timeout: 5 seconds)'
[2020-05-07 22:02:38,758: WARNING/MainProcess] Retrying (Retry(total=2, connect=None, read=None, redirect=None, status=None)) after connection broken by 'NewConnectionError('<urllib3.connection.HTTPConnection object at 0x7f48d76dcbe0>: Failed to establish a new connection: [Errno 111] Connection refused',)': /intake/v2/events
[2020-05-07 22:02:38,759: WARNING/MainProcess] Retrying (Retry(total=1, connect=None, read=None, redirect=None, status=None)) after connection broken by 'NewConnectionError('<urllib3.connection.HTTPConnection object at 0x7f48d76dcba8>: Failed to establish a new connection: [Errno 111] Connection refused',)': /intake/v2/events
[2020-05-07 22:02:38,759: WARNING/MainProcess] Retrying (Retry(total=0, connect=None, read=None, redirect=None, status=None)) after connection broken by 'NewConnectionError('<urllib3.connection.HTTPConnection object at 0x7f48d76dcc88>: Failed to establish a new connection: [Errno 111] Connection refused',)': /intake/v2/events
[2020-05-07 22:02:38,759: ERROR/MainProcess] Failed to submit message: 'Connection to APM Server timed out (url: http://127.0.0.1:8200/intake/v2/events, timeout: 5 seconds)'
[2020-05-07 22:03:07,492: WARNING/MainProcess] Retrying (Retry(total=2, connect=None, read=None, redirect=None, status=None)) after connection broken by 'NewConnectionError('<urllib3.connection.HTTPConnection object at 0x7f48d76c7438>: Failed to establish a new connection: [Errno 111] Connection refused',)': /intake/v2/events
[2020-05-07 22:03:07,493: WARNING/MainProcess] Retrying (Retry(total=1, connect=None, read=None, redirect=None, status=None)) after connection broken by 'NewConnectionError('<urllib3.connection.HTTPConnection object at 0x7f48d76c7f60>: Failed to establish a new connection: [Errno 111] Connection refused',)': /intake/v2/events
[2020-05-07 22:03:07,493: WARNING/MainProcess] Retrying (Retry(total=0, connect=None, read=None, redirect=None, status=None)) after connection broken by 'NewConnectionError('<urllib3.connection.HTTPConnection object at 0x7f48d76c7128>: Failed to establish a new connection: [Errno 111] Connection refused',)': /intake/v2/events
[2020-05-07 22:03:07,494: ERROR/MainProcess] Failed to submit message: 'Connection to APM Server timed out (url: http://127.0.0.1:8200/intake/v2/events, timeout: 5 seconds)'
[2020-05-08 07:06:00,870: WARNING/MainProcess] Retrying (Retry(total=2, connect=None, read=None, redirect=None, status=None)) after connection broken by 'NewConnectionError('<urllib3.connection.HTTPConnection object at 0x7f48d76dc6a0>: Failed to establish a new connection: [Errno 111] Connection refused',)': /config/v1/agents
[2020-05-08 07:06:00,870: WARNING/MainProcess] Retrying (Retry(total=1, connect=None, read=None, redirect=None, status=None)) after connection broken by 'NewConnectionError('<urllib3.connection.HTTPConnection object at 0x7f48d76dc048>: Failed to establish a new connection: [Errno 111] Connection refused',)': /config/v1/agents
[2020-05-08 07:06:00,870: WARNING/MainProcess] Retrying (Retry(total=0, connect=None, read=None, redirect=None, status=None)) after connection broken by 'NewConnectionError('<urllib3.connection.HTTPConnection object at 0x7f48d76dc898>: Failed to establish a new connection: [Errno 111] Connection refused',)': /config/v1/agents
[2020-05-08 07:06:04,188: WARNING/MainProcess] Retrying (Retry(total=2, connect=None, read=None, redirect=None, status=None)) after connection broken by 'NewConnectionError('<urllib3.connection.HTTPConnection object at 0x7f48d76dcb70>: Failed to establish a new connection: [Errno 111] Connection refused',)': /intake/v2/events
[2020-05-08 07:06:04,189: WARNING/MainProcess] Retrying (Retry(total=1, connect=None, read=None, redirect=None, status=None)) after connection broken by 'NewConnectionError('<urllib3.connection.HTTPConnection object at 0x7f48d76dc7f0>: Failed to establish a new connection: [Errno 111] Connection refused',)': /intake/v2/events
[2020-05-08 07:06:04,189: WARNING/MainProcess] Retrying (Retry(total=0, connect=None, read=None, redirect=None, status=None)) after connection broken by 'NewConnectionError('<urllib3.connection.HTTPConnection object at 0x7f48d76dca20>: Failed to establish a new connection: [Errno 111] Connection refused',)': /intake/v2/events
[2020-05-08 07:06:04,189: ERROR/MainProcess] Failed to submit message: 'Connection to APM Server timed out (url: http://127.0.0.1:8200/intake/v2/events, timeout: 5 seconds)'
[2020-05-08 07:06:33,507: WARNING/MainProcess] Retrying (Retry(total=2, connect=None, read=None, redirect=None, status=None)) after connection broken by 'NewConnectionError('<urllib3.connection.HTTPConnection object at 0x7f48d76c7198>: Failed to establish a new connection: [Errno 111] Connection refused',)': /intake/v2/events
[2020-05-08 07:06:33,507: WARNING/MainProcess] Retrying (Retry(total=1, connect=None, read=None, redirect=None, status=None)) after connection broken by 'NewConnectionError('<urllib3.connection.HTTPConnection object at 0x7f48d76c7f60>: Failed to establish a new connection: [Errno 111] Connection refused',)': /intake/v2/events
[2020-05-08 07:06:33,508: WARNING/MainProcess] Retrying (Retry(total=0, connect=None, read=None, redirect=None, status=None)) after connection broken by 'NewConnectionError('<urllib3.connection.HTTPConnection object at 0x7f48d76c7e80>: Failed to establish a new connection: [Errno 111] Connection refused',)': /intake/v2/events
[2020-05-08 07:06:33,508: ERROR/MainProcess] Failed to submit message: 'Connection to APM Server timed out (url: http://127.0.0.1:8200/intake/v2/events, timeout: 5 seconds)'
