[2020-05-05 23:25:59 +0800] [30458] [INFO] Starting gunicorn 20.0.4
[2020-05-05 23:25:59 +0800] [30458] [INFO] Listening at: http://0.0.0.0:8085 (30458)
[2020-05-05 23:25:59 +0800] [30458] [INFO] Using worker: eventlet
[2020-05-05 23:25:59 +0800] [30461] [INFO] Booting worker with pid: 30461
[2020-05-05 23:25:59 +0800] [30462] [INFO] Booting worker with pid: 30462
[2020-05-05 23:28:39 +0800] [30462] [INFO] Worker reloading: /home/et/backend_server/app/factory.py modified
[2020-05-05 23:28:39 +0800] [30462] [INFO] Worker exiting (pid: 30462)
[2020-05-05 23:28:39 +0800] [30461] [INFO] Worker reloading: /home/et/backend_server/app/factory.py modified
[2020-05-05 23:28:39 +0800] [30461] [INFO] Worker exiting (pid: 30461)
[2020-05-05 23:28:39 +0800] [31575] [INFO] Booting worker with pid: 31575
[2020-05-05 23:28:39 +0800] [31576] [INFO] Booting worker with pid: 31576
[2020-05-06 10:58:56 +0800] [30727] [INFO] Starting gunicorn 20.0.4
[2020-05-06 10:58:56 +0800] [30727] [INFO] Listening at: http://0.0.0.0:8085 (30727)
[2020-05-06 10:58:56 +0800] [30727] [INFO] Using worker: eventlet
[2020-05-06 10:58:56 +0800] [30731] [INFO] Booting worker with pid: 30731
[2020-05-06 10:58:56 +0800] [30732] [INFO] Booting worker with pid: 30732
[2020-05-06 11:08:19 +0800] [30731] [INFO] Worker reloading: /home/et/backend_server/app/factory.py modified
[2020-05-06 11:08:19 +0800] [30732] [INFO] Worker reloading: /home/et/backend_server/app/factory.py modified
[2020-05-06 11:08:19 +0800] [30731] [INFO] Worker exiting (pid: 30731)
[2020-05-06 11:08:19 +0800] [30732] [INFO] Worker exiting (pid: 30732)
[2020-05-06 11:08:19 +0800] [2068] [INFO] Booting worker with pid: 2068
[2020-05-06 11:08:19 +0800] [2069] [INFO] Booting worker with pid: 2069
[2020-05-06 11:08:39 +0800] [2068] [INFO] Worker reloading: /home/et/backend_server/app/factory.py modified
[2020-05-06 11:08:39 +0800] [2068] [INFO] Worker exiting (pid: 2068)
[2020-05-06 11:08:39 +0800] [2232] [INFO] Booting worker with pid: 2232
[2020-05-06 11:08:39 +0800] [2069] [INFO] Worker reloading: /home/et/backend_server/app/factory.py modified
[2020-05-06 11:08:39 +0800] [2069] [INFO] Worker exiting (pid: 2069)
[2020-05-06 11:08:39 +0800] [2234] [INFO] Booting worker with pid: 2234
[2020-05-06 11:13:18 +0800] [2232] [INFO] Worker reloading: /home/et/backend_server/app/factory.py modified
[2020-05-06 11:13:18 +0800] [2232] [INFO] Worker exiting (pid: 2232)
[2020-05-06 11:13:19 +0800] [4216] [INFO] Booting worker with pid: 4216
[2020-05-06 11:13:19 +0800] [2234] [INFO] Worker reloading: /home/et/backend_server/app/factory.py modified
[2020-05-06 11:13:19 +0800] [2234] [INFO] Worker exiting (pid: 2234)
[2020-05-06 11:13:19 +0800] [4218] [INFO] Booting worker with pid: 4218
[2020-05-06 11:14:38 +0800] [4216] [INFO] Worker reloading: /home/et/backend_server/app/factory.py modified
[2020-05-06 11:14:38 +0800] [4216] [INFO] Worker exiting (pid: 4216)
[2020-05-06 11:14:38 +0800] [4805] [INFO] Booting worker with pid: 4805
[2020-05-06 11:14:38 +0800] [4805] [ERROR] unexpected indent (factory.py, line 43)
Traceback (most recent call last):
  File "/usr/local/lib/python3.6/site-packages/gunicorn/workers/base.py", line 144, in load_wsgi
    self.wsgi = self.app.wsgi()
  File "/usr/local/lib/python3.6/site-packages/gunicorn/app/base.py", line 67, in wsgi
    self.callable = self.load()
  File "/usr/local/lib/python3.6/site-packages/gunicorn/app/wsgiapp.py", line 49, in load
    return self.load_wsgiapp()
  File "/usr/local/lib/python3.6/site-packages/gunicorn/app/wsgiapp.py", line 39, in load_wsgiapp
    return util.import_app(self.app_uri)
  File "/usr/local/lib/python3.6/site-packages/gunicorn/util.py", line 358, in import_app
    mod = importlib.import_module(module)
  File "/usr/lib64/python3.6/importlib/__init__.py", line 126, in import_module
    return _bootstrap._gcd_import(name[level:], package, level)
  File "<frozen importlib._bootstrap>", line 994, in _gcd_import
  File "<frozen importlib._bootstrap>", line 971, in _find_and_load
  File "<frozen importlib._bootstrap>", line 955, in _find_and_load_unlocked
  File "<frozen importlib._bootstrap>", line 665, in _load_unlocked
  File "<frozen importlib._bootstrap_external>", line 678, in exec_module
  File "<frozen importlib._bootstrap>", line 219, in _call_with_frames_removed
  File "/home/et/backend_server/wsgi_gunicorn.py", line 1, in <module>
    from app.factory import create_app, celery_app
  File "/home/et/backend_server/app/factory.py", line 43
    register_api(app=app, routers=router)
    ^
IndentationError: unexpected indent
[2020-05-06 11:14:38 +0800] [4805] [ERROR] Exception in worker process
Traceback (most recent call last):
  File "/usr/local/lib/python3.6/site-packages/gunicorn/workers/base.py", line 144, in load_wsgi
    self.wsgi = self.app.wsgi()
  File "/usr/local/lib/python3.6/site-packages/gunicorn/app/base.py", line 67, in wsgi
    self.callable = self.load()
  File "/usr/local/lib/python3.6/site-packages/gunicorn/app/wsgiapp.py", line 49, in load
    return self.load_wsgiapp()
  File "/usr/local/lib/python3.6/site-packages/gunicorn/app/wsgiapp.py", line 39, in load_wsgiapp
    return util.import_app(self.app_uri)
  File "/usr/local/lib/python3.6/site-packages/gunicorn/util.py", line 358, in import_app
    mod = importlib.import_module(module)
  File "/usr/lib64/python3.6/importlib/__init__.py", line 126, in import_module
    return _bootstrap._gcd_import(name[level:], package, level)
  File "<frozen importlib._bootstrap>", line 994, in _gcd_import
  File "<frozen importlib._bootstrap>", line 971, in _find_and_load
  File "<frozen importlib._bootstrap>", line 955, in _find_and_load_unlocked
  File "<frozen importlib._bootstrap>", line 665, in _load_unlocked
  File "<frozen importlib._bootstrap_external>", line 678, in exec_module
  File "<frozen importlib._bootstrap>", line 219, in _call_with_frames_removed
  File "/home/et/backend_server/wsgi_gunicorn.py", line 1, in <module>
    from app.factory import create_app, celery_app
  File "/home/et/backend_server/app/factory.py", line 43
    register_api(app=app, routers=router)
    ^
IndentationError: unexpected indent

During handling of the above exception, another exception occurred:

Traceback (most recent call last):
  File "/usr/local/lib/python3.6/site-packages/gunicorn/arbiter.py", line 583, in spawn_worker
    worker.init_process()
  File "/usr/local/lib/python3.6/site-packages/gunicorn/workers/geventlet.py", line 99, in init_process
    super().init_process()
  File "/usr/local/lib/python3.6/site-packages/gunicorn/workers/base.py", line 119, in init_process
    self.load_wsgi()
  File "/usr/local/lib/python3.6/site-packages/gunicorn/workers/base.py", line 157, in load_wsgi
    self.reloader.add_extra_file(exc_val.filename)
AttributeError: 'NoneType' object has no attribute 'add_extra_file'
[2020-05-06 11:14:38 +0800] [4805] [INFO] Worker exiting (pid: 4805)
[2020-05-06 11:14:38 +0800] [4218] [INFO] Worker reloading: /home/et/backend_server/app/factory.py modified
[2020-05-06 11:14:38 +0800] [4218] [INFO] Worker exiting (pid: 4218)
[2020-05-06 11:14:38 +0800] [30727] [INFO] Shutting down: Master
[2020-05-06 11:14:38 +0800] [30727] [INFO] Reason: Worker failed to boot.
[2020-05-06 11:15:18 +0800] [5051] [INFO] Starting gunicorn 20.0.4
[2020-05-06 11:15:18 +0800] [5051] [INFO] Listening at: http://0.0.0.0:8085 (5051)
[2020-05-06 11:15:18 +0800] [5051] [INFO] Using worker: eventlet
[2020-05-06 11:15:18 +0800] [5054] [INFO] Booting worker with pid: 5054
[2020-05-06 11:15:18 +0800] [5055] [INFO] Booting worker with pid: 5055
[2020-05-06 11:21:14 +0800] [5055] [INFO] Worker reloading: /home/et/backend_server/app/factory.py modified
[2020-05-06 11:21:14 +0800] [5054] [INFO] Worker reloading: /home/et/backend_server/app/factory.py modified
[2020-05-06 11:21:14 +0800] [5055] [INFO] Worker exiting (pid: 5055)
[2020-05-06 11:21:14 +0800] [5054] [INFO] Worker exiting (pid: 5054)
[2020-05-06 11:21:14 +0800] [7534] [INFO] Booting worker with pid: 7534
[2020-05-06 11:21:14 +0800] [7535] [INFO] Booting worker with pid: 7535
[2020-05-06 11:36:25 +0800] [7535] [INFO] Worker reloading: /home/et/backend_server/app/factory.py modified
[2020-05-06 11:36:25 +0800] [7534] [INFO] Worker reloading: /home/et/backend_server/app/factory.py modified
[2020-05-06 11:36:25 +0800] [7535] [INFO] Worker exiting (pid: 7535)
[2020-05-06 11:36:25 +0800] [7534] [INFO] Worker exiting (pid: 7534)
[2020-05-06 11:36:25 +0800] [13781] [INFO] Booting worker with pid: 13781
[2020-05-06 11:36:25 +0800] [13782] [INFO] Booting worker with pid: 13782
[2020-05-06 11:36:31 +0800] [13781] [INFO] Worker reloading: /home/et/backend_server/app/factory.py modified
[2020-05-06 11:36:31 +0800] [13781] [INFO] Worker exiting (pid: 13781)
[2020-05-06 11:36:31 +0800] [13782] [INFO] Worker reloading: /home/et/backend_server/app/factory.py modified
[2020-05-06 11:36:31 +0800] [13782] [INFO] Worker exiting (pid: 13782)
[2020-05-06 11:36:31 +0800] [13796] [INFO] Booting worker with pid: 13796
[2020-05-06 11:36:31 +0800] [13797] [INFO] Booting worker with pid: 13797
[2020-05-06 11:41:56 +0800] [5051] [INFO] Handling signal: int
[2020-05-06 11:41:56 +0800] [13797] [INFO] Worker exiting (pid: 13797)
[2020-05-06 11:41:56 +0800] [13796] [INFO] Worker exiting (pid: 13796)
[2020-05-06 11:41:56 +0800] [5051] [INFO] Shutting down: Master
[2020-05-06 11:42:02 +0800] [16146] [INFO] Starting gunicorn 20.0.4
[2020-05-06 11:42:02 +0800] [16146] [INFO] Listening at: http://0.0.0.0:8085 (16146)
[2020-05-06 11:42:02 +0800] [16146] [INFO] Using worker: eventlet
[2020-05-06 11:42:02 +0800] [16149] [INFO] Booting worker with pid: 16149
[2020-05-06 11:42:02 +0800] [16150] [INFO] Booting worker with pid: 16150
[2020-05-06 11:45:50 +0800] [16149] [INFO] Worker reloading: /home/et/backend_server/app/api/task_service.py modified
[2020-05-06 11:45:50 +0800] [16150] [INFO] Worker reloading: /home/et/backend_server/app/api/task_service.py modified
[2020-05-06 11:45:50 +0800] [16149] [INFO] Worker exiting (pid: 16149)
[2020-05-06 11:45:50 +0800] [16150] [INFO] Worker exiting (pid: 16150)
[2020-05-06 11:45:50 +0800] [17804] [INFO] Booting worker with pid: 17804
[2020-05-06 11:45:50 +0800] [17805] [INFO] Booting worker with pid: 17805
[2020-05-06 20:40:31 +0800] [17804] [INFO] Worker reloading: /home/et/backend_server/app/api/account_service.py modified
[2020-05-06 20:40:31 +0800] [17805] [INFO] Worker reloading: /home/et/backend_server/app/api/account_service.py modified
[2020-05-06 20:40:31 +0800] [17804] [INFO] Worker exiting (pid: 17804)
[2020-05-06 20:40:31 +0800] [17805] [INFO] Worker exiting (pid: 17805)
[2020-05-06 20:40:31 +0800] [26293] [INFO] Booting worker with pid: 26293
[2020-05-06 20:40:31 +0800] [26294] [INFO] Booting worker with pid: 26294
[2020-05-06 20:44:04 +0800] [26293] [INFO] Worker reloading: /home/et/backend_server/app/api/account_service.py modified
[2020-05-06 20:44:04 +0800] [26293] [INFO] Worker exiting (pid: 26293)
[2020-05-06 20:44:04 +0800] [26294] [INFO] Worker reloading: /home/et/backend_server/app/api/account_service.py modified
[2020-05-06 20:44:04 +0800] [26294] [INFO] Worker exiting (pid: 26294)
[2020-05-06 20:44:04 +0800] [27709] [INFO] Booting worker with pid: 27709
[2020-05-06 20:44:04 +0800] [27710] [INFO] Booting worker with pid: 27710
[2020-05-06 20:45:08 +0800] [27709] [INFO] Worker reloading: /home/et/backend_server/app/api/account_service.py modified
[2020-05-06 20:45:08 +0800] [27709] [INFO] Worker exiting (pid: 27709)
[2020-05-06 20:45:08 +0800] [27710] [INFO] Worker reloading: /home/et/backend_server/app/api/account_service.py modified
[2020-05-06 20:45:08 +0800] [27710] [INFO] Worker exiting (pid: 27710)
[2020-05-06 20:45:08 +0800] [28261] [INFO] Booting worker with pid: 28261
[2020-05-06 20:45:08 +0800] [28262] [INFO] Booting worker with pid: 28262
[2020-05-06 20:51:40 +0800] [28262] [INFO] Worker reloading: /home/et/backend_server/app/api/account_service.py modified
[2020-05-06 20:51:40 +0800] [28261] [INFO] Worker reloading: /home/et/backend_server/app/api/account_service.py modified
[2020-05-06 20:51:40 +0800] [28262] [INFO] Worker exiting (pid: 28262)
[2020-05-06 20:51:40 +0800] [28261] [INFO] Worker exiting (pid: 28261)
[2020-05-06 20:51:40 +0800] [31402] [INFO] Booting worker with pid: 31402
[2020-05-06 20:51:40 +0800] [31404] [INFO] Booting worker with pid: 31404
[2020-05-06 20:52:40 +0800] [31402] [INFO] Worker reloading: /home/et/backend_server/app/api/account_service.py modified
[2020-05-06 20:52:40 +0800] [31402] [INFO] Worker exiting (pid: 31402)
[2020-05-06 20:52:40 +0800] [31404] [INFO] Worker reloading: /home/et/backend_server/app/api/account_service.py modified
[2020-05-06 20:52:40 +0800] [31404] [INFO] Worker exiting (pid: 31404)
[2020-05-06 20:52:40 +0800] [31922] [INFO] Booting worker with pid: 31922
[2020-05-06 20:52:40 +0800] [31923] [INFO] Booting worker with pid: 31923
[2020-05-06 20:52:55 +0800] [31922] [INFO] Worker reloading: /home/et/backend_server/app/api/account_service.py modified
[2020-05-06 20:52:55 +0800] [31922] [INFO] Worker exiting (pid: 31922)
[2020-05-06 20:52:55 +0800] [31923] [INFO] Worker reloading: /home/et/backend_server/app/api/account_service.py modified
[2020-05-06 20:52:55 +0800] [31923] [INFO] Worker exiting (pid: 31923)
[2020-05-06 20:52:55 +0800] [32022] [INFO] Booting worker with pid: 32022
[2020-05-06 20:52:55 +0800] [32023] [INFO] Booting worker with pid: 32023
[2020-05-06 20:53:53 +0800] [32023] [INFO] Worker reloading: /home/et/backend_server/app/api/account_service.py modified
[2020-05-06 20:53:53 +0800] [32023] [INFO] Worker exiting (pid: 32023)
[2020-05-06 20:53:53 +0800] [32022] [INFO] Worker reloading: /home/et/backend_server/app/api/account_service.py modified
[2020-05-06 20:53:53 +0800] [32022] [INFO] Worker exiting (pid: 32022)
[2020-05-06 20:53:53 +0800] [32447] [INFO] Booting worker with pid: 32447
[2020-05-06 20:53:54 +0800] [32448] [INFO] Booting worker with pid: 32448
[2020-05-06 21:01:08 +0800] [32448] [INFO] Worker reloading: /home/et/backend_server/app/api/oem_service.py modified
[2020-05-06 21:01:08 +0800] [32447] [INFO] Worker reloading: /home/et/backend_server/app/api/oem_service.py modified
[2020-05-06 21:01:08 +0800] [32448] [INFO] Worker exiting (pid: 32448)
[2020-05-06 21:01:08 +0800] [32447] [INFO] Worker exiting (pid: 32447)
[2020-05-06 21:01:08 +0800] [3118] [INFO] Booting worker with pid: 3118
[2020-05-06 21:01:08 +0800] [3119] [INFO] Booting worker with pid: 3119
[2020-05-06 21:15:33 +0800] [3119] [INFO] Worker reloading: /home/et/backend_server/app/api/oem_service.py modified
[2020-05-06 21:15:33 +0800] [3118] [INFO] Worker reloading: /home/et/backend_server/app/api/oem_service.py modified
[2020-05-06 21:15:33 +0800] [3119] [INFO] Worker exiting (pid: 3119)
[2020-05-06 21:15:33 +0800] [3118] [INFO] Worker exiting (pid: 3118)
[2020-05-06 21:15:34 +0800] [10667] [INFO] Booting worker with pid: 10667
[2020-05-06 21:15:34 +0800] [10668] [INFO] Booting worker with pid: 10668
[2020-05-06 21:15:40 +0800] [10667] [INFO] Worker reloading: /home/et/backend_server/app/api/work_station.py modified
[2020-05-06 21:15:40 +0800] [10667] [INFO] Worker exiting (pid: 10667)
[2020-05-06 21:15:40 +0800] [10668] [INFO] Worker reloading: /home/et/backend_server/app/api/work_station.py modified
[2020-05-06 21:15:40 +0800] [10668] [INFO] Worker exiting (pid: 10668)
[2020-05-06 21:15:40 +0800] [10714] [INFO] Booting worker with pid: 10714
[2020-05-06 21:15:40 +0800] [10715] [INFO] Booting worker with pid: 10715
[2020-05-06 21:16:36 +0800] [10715] [ERROR] Error handling request /merchants/ban_mer
Traceback (most recent call last):
  File "/usr/local/lib/python3.6/site-packages/gunicorn/workers/base_async.py", line 55, in handle
    self.handle_request(listener_name, req, client, addr)
  File "/usr/local/lib/python3.6/site-packages/gunicorn/workers/base_async.py", line 106, in handle_request
    respiter = self.wsgi(environ, resp.start_response)
  File "/usr/local/lib/python3.6/site-packages/flask/app.py", line 2463, in __call__
    return self.wsgi_app(environ, start_response)
  File "/usr/local/lib/python3.6/site-packages/flask/app.py", line 2449, in wsgi_app
    response = self.handle_exception(e)
  File "/usr/local/lib64/python3.6/site-packages/flask_cors/extension.py", line 161, in wrapped_function
    return cors_after_request(app.make_response(f(*args, **kwargs)))
  File "/usr/local/lib/python3.6/site-packages/flask/app.py", line 1866, in handle_exception
    reraise(exc_type, exc_value, tb)
  File "/usr/local/lib/python3.6/site-packages/flask/_compat.py", line 39, in reraise
    raise value
  File "/usr/local/lib/python3.6/site-packages/flask/app.py", line 2446, in wsgi_app
    response = self.full_dispatch_request()
  File "/usr/local/lib/python3.6/site-packages/flask/app.py", line 1951, in full_dispatch_request
    rv = self.handle_user_exception(e)
  File "/usr/local/lib64/python3.6/site-packages/flask_cors/extension.py", line 161, in wrapped_function
    return cors_after_request(app.make_response(f(*args, **kwargs)))
  File "/usr/local/lib/python3.6/site-packages/flask/app.py", line 1820, in handle_user_exception
    reraise(exc_type, exc_value, tb)
  File "/usr/local/lib/python3.6/site-packages/flask/_compat.py", line 39, in reraise
    raise value
  File "/usr/local/lib/python3.6/site-packages/flask/app.py", line 1949, in full_dispatch_request
    rv = self.dispatch_request()
  File "/usr/local/lib/python3.6/site-packages/flask/app.py", line 1935, in dispatch_request
    return self.view_functions[rule.endpoint](**req.view_args)
  File "/home/et/backend_server/app/api/oem_service.py", line 317, in ban_mer
    user = db.session.query(ETMerchants).filter(ETMerchants.id == mar_id).first()
NameError: name 'mar_id' is not defined
[2020-05-06 21:18:59 +0800] [10715] [INFO] Worker reloading: /home/et/backend_server/app/api/oem_service.py modified
[2020-05-06 21:18:59 +0800] [10715] [INFO] Worker exiting (pid: 10715)
[2020-05-06 21:18:59 +0800] [10714] [INFO] Worker reloading: /home/et/backend_server/app/api/oem_service.py modified
[2020-05-06 21:18:59 +0800] [10714] [INFO] Worker exiting (pid: 10714)
[2020-05-06 21:18:59 +0800] [13781] [INFO] Booting worker with pid: 13781
[2020-05-06 21:18:59 +0800] [13782] [INFO] Booting worker with pid: 13782
[2020-05-06 21:26:44 +0800] [13782] [INFO] Worker reloading: /home/et/backend_server/app/api/oem_service.py modified
[2020-05-06 21:26:44 +0800] [13781] [INFO] Worker reloading: /home/et/backend_server/app/api/oem_service.py modified
[2020-05-06 21:26:44 +0800] [13782] [INFO] Worker exiting (pid: 13782)
[2020-05-06 21:26:44 +0800] [13781] [INFO] Worker exiting (pid: 13781)
[2020-05-06 21:26:44 +0800] [17172] [INFO] Booting worker with pid: 17172
[2020-05-06 21:26:44 +0800] [17173] [INFO] Booting worker with pid: 17173
[2020-05-06 21:31:13 +0800] [17173] [ERROR] Error handling request /merchants/registered
Traceback (most recent call last):
  File "/usr/local/lib/python3.6/site-packages/gunicorn/workers/base_async.py", line 55, in handle
    self.handle_request(listener_name, req, client, addr)
  File "/usr/local/lib/python3.6/site-packages/gunicorn/workers/base_async.py", line 106, in handle_request
    respiter = self.wsgi(environ, resp.start_response)
  File "/usr/local/lib/python3.6/site-packages/flask/app.py", line 2463, in __call__
    return self.wsgi_app(environ, start_response)
  File "/usr/local/lib/python3.6/site-packages/flask/app.py", line 2449, in wsgi_app
    response = self.handle_exception(e)
  File "/usr/local/lib64/python3.6/site-packages/flask_cors/extension.py", line 161, in wrapped_function
    return cors_after_request(app.make_response(f(*args, **kwargs)))
  File "/usr/local/lib/python3.6/site-packages/flask/app.py", line 1866, in handle_exception
    reraise(exc_type, exc_value, tb)
  File "/usr/local/lib/python3.6/site-packages/flask/_compat.py", line 39, in reraise
    raise value
  File "/usr/local/lib/python3.6/site-packages/flask/app.py", line 2446, in wsgi_app
    response = self.full_dispatch_request()
  File "/usr/local/lib/python3.6/site-packages/flask/app.py", line 1951, in full_dispatch_request
    rv = self.handle_user_exception(e)
  File "/usr/local/lib64/python3.6/site-packages/flask_cors/extension.py", line 161, in wrapped_function
    return cors_after_request(app.make_response(f(*args, **kwargs)))
  File "/usr/local/lib/python3.6/site-packages/flask/app.py", line 1820, in handle_user_exception
    reraise(exc_type, exc_value, tb)
  File "/usr/local/lib/python3.6/site-packages/flask/_compat.py", line 39, in reraise
    raise value
  File "/usr/local/lib/python3.6/site-packages/flask/app.py", line 1949, in full_dispatch_request
    rv = self.dispatch_request()
  File "/usr/local/lib/python3.6/site-packages/flask/app.py", line 1935, in dispatch_request
    return self.view_functions[rule.endpoint](**req.view_args)
  File "/home/et/backend_server/app/utils/auth.py", line 143, in wrapper
    return f(*args, **kwargs)
  File "/home/et/backend_server/app/api/oem_service.py", line 75, in registered
    user = db.session.query(EtAccount).filter(ETMerchants.name == username).first()
AttributeError: type object 'ETMerchants' has no attribute 'name'
[2020-05-06 21:31:53 +0800] [17172] [ERROR] Error handling request /merchants/registered
Traceback (most recent call last):
  File "/usr/local/lib/python3.6/site-packages/gunicorn/workers/base_async.py", line 55, in handle
    self.handle_request(listener_name, req, client, addr)
  File "/usr/local/lib/python3.6/site-packages/gunicorn/workers/base_async.py", line 106, in handle_request
    respiter = self.wsgi(environ, resp.start_response)
  File "/usr/local/lib/python3.6/site-packages/flask/app.py", line 2463, in __call__
    return self.wsgi_app(environ, start_response)
  File "/usr/local/lib/python3.6/site-packages/flask/app.py", line 2449, in wsgi_app
    response = self.handle_exception(e)
  File "/usr/local/lib64/python3.6/site-packages/flask_cors/extension.py", line 161, in wrapped_function
    return cors_after_request(app.make_response(f(*args, **kwargs)))
  File "/usr/local/lib/python3.6/site-packages/flask/app.py", line 1866, in handle_exception
    reraise(exc_type, exc_value, tb)
  File "/usr/local/lib/python3.6/site-packages/flask/_compat.py", line 39, in reraise
    raise value
  File "/usr/local/lib/python3.6/site-packages/flask/app.py", line 2446, in wsgi_app
    response = self.full_dispatch_request()
  File "/usr/local/lib/python3.6/site-packages/flask/app.py", line 1951, in full_dispatch_request
    rv = self.handle_user_exception(e)
  File "/usr/local/lib64/python3.6/site-packages/flask_cors/extension.py", line 161, in wrapped_function
    return cors_after_request(app.make_response(f(*args, **kwargs)))
  File "/usr/local/lib/python3.6/site-packages/flask/app.py", line 1820, in handle_user_exception
    reraise(exc_type, exc_value, tb)
  File "/usr/local/lib/python3.6/site-packages/flask/_compat.py", line 39, in reraise
    raise value
  File "/usr/local/lib/python3.6/site-packages/flask/app.py", line 1949, in full_dispatch_request
    rv = self.dispatch_request()
  File "/usr/local/lib/python3.6/site-packages/flask/app.py", line 1935, in dispatch_request
    return self.view_functions[rule.endpoint](**req.view_args)
  File "/home/et/backend_server/app/utils/auth.py", line 143, in wrapper
    return f(*args, **kwargs)
  File "/home/et/backend_server/app/api/oem_service.py", line 75, in registered
    user = db.session.query(EtAccount).filter(ETMerchants.name == username).first()
AttributeError: type object 'ETMerchants' has no attribute 'name'
[2020-05-06 21:31:55 +0800] [17173] [INFO] Worker reloading: /home/et/backend_server/app/api/oem_service.py modified
[2020-05-06 21:31:55 +0800] [17172] [INFO] Worker reloading: /home/et/backend_server/app/api/oem_service.py modified
[2020-05-06 21:31:55 +0800] [17173] [INFO] Worker exiting (pid: 17173)
[2020-05-06 21:31:55 +0800] [17172] [INFO] Worker exiting (pid: 17172)
[2020-05-06 21:31:56 +0800] [19614] [INFO] Booting worker with pid: 19614
[2020-05-06 21:31:56 +0800] [19615] [INFO] Booting worker with pid: 19615
[2020-05-06 22:04:14 +0800] [19614] [INFO] Worker reloading: /home/et/backend_server/app/api/work_station.py modified
[2020-05-06 22:04:14 +0800] [19615] [INFO] Worker reloading: /home/et/backend_server/app/api/work_station.py modified
[2020-05-06 22:04:14 +0800] [19614] [INFO] Worker exiting (pid: 19614)
[2020-05-06 22:04:14 +0800] [19615] [INFO] Worker exiting (pid: 19615)
[2020-05-06 22:04:14 +0800] [871] [INFO] Booting worker with pid: 871
[2020-05-06 22:04:14 +0800] [874] [INFO] Booting worker with pid: 874
[2020-05-06 22:05:29 +0800] [871] [INFO] Worker reloading: /home/et/backend_server/app/api/work_station.py modified
[2020-05-06 22:05:29 +0800] [871] [INFO] Worker exiting (pid: 871)
[2020-05-06 22:05:29 +0800] [874] [INFO] Worker reloading: /home/et/backend_server/app/api/work_station.py modified
[2020-05-06 22:05:29 +0800] [874] [INFO] Worker exiting (pid: 874)
[2020-05-06 22:05:29 +0800] [1378] [INFO] Booting worker with pid: 1378
[2020-05-06 22:05:29 +0800] [1379] [INFO] Booting worker with pid: 1379
[2020-05-06 22:08:35 +0800] [1379] [INFO] Worker reloading: /home/et/backend_server/app/api/work_station.py modified
[2020-05-06 22:08:35 +0800] [1378] [INFO] Worker reloading: /home/et/backend_server/app/api/work_station.py modified
[2020-05-06 22:08:35 +0800] [1379] [INFO] Worker exiting (pid: 1379)
[2020-05-06 22:08:35 +0800] [1378] [INFO] Worker exiting (pid: 1378)
[2020-05-06 22:08:35 +0800] [2656] [INFO] Booting worker with pid: 2656
[2020-05-06 22:08:35 +0800] [2657] [INFO] Booting worker with pid: 2657
[2020-05-07 10:18:38 +0800] [2656] [INFO] Worker reloading: /home/et/backend_server/app/api/oem_service.py modified
[2020-05-07 10:18:38 +0800] [2656] [INFO] Worker exiting (pid: 2656)
[2020-05-07 10:18:38 +0800] [18672] [INFO] Booting worker with pid: 18672
[2020-05-07 10:18:38 +0800] [2657] [INFO] Worker reloading: /home/et/backend_server/app/api/oem_service.py modified
[2020-05-07 10:18:38 +0800] [2657] [INFO] Worker exiting (pid: 2657)
[2020-05-07 10:18:38 +0800] [18674] [INFO] Booting worker with pid: 18674
[2020-05-07 10:20:54 +0800] [18672] [INFO] Worker reloading: /home/et/backend_server/app/api/oem_service.py modified
[2020-05-07 10:20:54 +0800] [18672] [INFO] Worker exiting (pid: 18672)
[2020-05-07 10:20:54 +0800] [18674] [INFO] Worker reloading: /home/et/backend_server/app/api/oem_service.py modified
[2020-05-07 10:20:54 +0800] [18674] [INFO] Worker exiting (pid: 18674)
[2020-05-07 10:20:54 +0800] [19792] [INFO] Booting worker with pid: 19792
[2020-05-07 10:20:54 +0800] [19794] [INFO] Booting worker with pid: 19794
[2020-05-07 10:21:36 +0800] [19792] [INFO] Worker reloading: /home/et/backend_server/app/api/oem_service.py modified
[2020-05-07 10:21:36 +0800] [19792] [INFO] Worker exiting (pid: 19792)
[2020-05-07 10:21:36 +0800] [19794] [INFO] Worker reloading: /home/et/backend_server/app/api/oem_service.py modified
[2020-05-07 10:21:36 +0800] [19794] [INFO] Worker exiting (pid: 19794)
[2020-05-07 10:21:36 +0800] [20091] [INFO] Booting worker with pid: 20091
[2020-05-07 10:21:36 +0800] [20092] [INFO] Booting worker with pid: 20092
[2020-05-07 10:41:08 +0800] [20092] [ERROR] Error handling request /merchants/registered
Traceback (most recent call last):
  File "/usr/local/lib/python3.6/site-packages/gunicorn/workers/base_async.py", line 55, in handle
    self.handle_request(listener_name, req, client, addr)
  File "/usr/local/lib/python3.6/site-packages/gunicorn/workers/base_async.py", line 106, in handle_request
    respiter = self.wsgi(environ, resp.start_response)
  File "/usr/local/lib/python3.6/site-packages/flask/app.py", line 2463, in __call__
    return self.wsgi_app(environ, start_response)
  File "/usr/local/lib/python3.6/site-packages/flask/app.py", line 2449, in wsgi_app
    response = self.handle_exception(e)
  File "/usr/local/lib64/python3.6/site-packages/flask_cors/extension.py", line 161, in wrapped_function
    return cors_after_request(app.make_response(f(*args, **kwargs)))
  File "/usr/local/lib/python3.6/site-packages/flask/app.py", line 1866, in handle_exception
    reraise(exc_type, exc_value, tb)
  File "/usr/local/lib/python3.6/site-packages/flask/_compat.py", line 39, in reraise
    raise value
  File "/usr/local/lib/python3.6/site-packages/flask/app.py", line 2446, in wsgi_app
    response = self.full_dispatch_request()
  File "/usr/local/lib/python3.6/site-packages/flask/app.py", line 1951, in full_dispatch_request
    rv = self.handle_user_exception(e)
  File "/usr/local/lib64/python3.6/site-packages/flask_cors/extension.py", line 161, in wrapped_function
    return cors_after_request(app.make_response(f(*args, **kwargs)))
  File "/usr/local/lib/python3.6/site-packages/flask/app.py", line 1820, in handle_user_exception
    reraise(exc_type, exc_value, tb)
  File "/usr/local/lib/python3.6/site-packages/flask/_compat.py", line 39, in reraise
    raise value
  File "/usr/local/lib/python3.6/site-packages/flask/app.py", line 1949, in full_dispatch_request
    rv = self.dispatch_request()
  File "/usr/local/lib/python3.6/site-packages/flask/app.py", line 1935, in dispatch_request
    return self.view_functions[rule.endpoint](**req.view_args)
  File "/home/et/backend_server/app/utils/auth.py", line 143, in wrapper
    return f(*args, **kwargs)
  File "/home/et/backend_server/app/api/oem_service.py", line 80, in registered
    new_user = EtAccount(name=username, password=password_hash, role_id=1, ip=ip)
  File "<string>", line 4, in __init__
  File "/usr/local/lib/python3.6/site-packages/sqlalchemy/orm/state.py", line 441, in _initialize_instance
    manager.dispatch.init_failure(self, args, kwargs)
  File "/usr/local/lib/python3.6/site-packages/sqlalchemy/util/langhelpers.py", line 68, in __exit__
    compat.reraise(exc_type, exc_value, exc_tb)
  File "/usr/local/lib/python3.6/site-packages/sqlalchemy/util/compat.py", line 129, in reraise
    raise value
  File "/usr/local/lib/python3.6/site-packages/sqlalchemy/orm/state.py", line 438, in _initialize_instance
    return manager.original_init(*mixed[1:], **kwargs)
  File "/usr/local/lib/python3.6/site-packages/sqlalchemy/ext/declarative/base.py", line 834, in _declarative_constructor
    "%r is an invalid keyword argument for %s" % (k, cls_.__name__)
TypeError: 'ip' is an invalid keyword argument for EtAccount
[2020-05-07 10:43:35 +0800] [20091] [INFO] Worker reloading: /home/et/backend_server/app/models/accounts.py modified
[2020-05-07 10:43:35 +0800] [20091] [INFO] Worker exiting (pid: 20091)
[2020-05-07 10:43:35 +0800] [20092] [INFO] Worker reloading: /home/et/backend_server/app/models/accounts.py modified
[2020-05-07 10:43:35 +0800] [20092] [INFO] Worker exiting (pid: 20092)
[2020-05-07 10:43:35 +0800] [29869] [INFO] Booting worker with pid: 29869
[2020-05-07 10:43:35 +0800] [29870] [INFO] Booting worker with pid: 29870
[2020-05-07 10:45:18 +0800] [29870] [ERROR] Error handling request /merchants/registered
Traceback (most recent call last):
  File "/usr/local/lib/python3.6/site-packages/sqlalchemy/engine/base.py", line 1244, in _execute_context
    cursor, statement, parameters, context
  File "/usr/local/lib/python3.6/site-packages/sqlalchemy/engine/default.py", line 552, in do_execute
    cursor.execute(statement, parameters)
  File "/usr/local/lib64/python3.6/site-packages/elasticapm/instrumentation/packages/dbapi2.py", line 209, in execute
    return self._trace_sql(self.__wrapped__.execute, sql, params)
  File "/usr/local/lib64/python3.6/site-packages/elasticapm/instrumentation/packages/dbapi2.py", line 238, in _trace_sql
    return method(sql, params)
  File "/usr/local/lib/python3.6/site-packages/pymysql/cursors.py", line 170, in execute
    result = self._query(query)
  File "/usr/local/lib/python3.6/site-packages/pymysql/cursors.py", line 328, in _query
    conn.query(q)
  File "/usr/local/lib/python3.6/site-packages/pymysql/connections.py", line 516, in query
    self._affected_rows = self._read_query_result(unbuffered=unbuffered)
  File "/usr/local/lib/python3.6/site-packages/pymysql/connections.py", line 727, in _read_query_result
    result.read()
  File "/usr/local/lib/python3.6/site-packages/pymysql/connections.py", line 1066, in read
    first_packet = self.connection._read_packet()
  File "/usr/local/lib/python3.6/site-packages/pymysql/connections.py", line 683, in _read_packet
    packet.check_error()
  File "/usr/local/lib/python3.6/site-packages/pymysql/protocol.py", line 220, in check_error
    err.raise_mysql_exception(self._data)
  File "/usr/local/lib/python3.6/site-packages/pymysql/err.py", line 109, in raise_mysql_exception
    raise errorclass(errno, errval)
pymysql.err.InternalError: (1054, "Unknown column 'et_accounts.mobile' in 'field list'")

The above exception was the direct cause of the following exception:

Traceback (most recent call last):
  File "/usr/local/lib/python3.6/site-packages/gunicorn/workers/base_async.py", line 55, in handle
    self.handle_request(listener_name, req, client, addr)
  File "/usr/local/lib/python3.6/site-packages/gunicorn/workers/base_async.py", line 106, in handle_request
    respiter = self.wsgi(environ, resp.start_response)
  File "/usr/local/lib/python3.6/site-packages/flask/app.py", line 2463, in __call__
    return self.wsgi_app(environ, start_response)
  File "/usr/local/lib/python3.6/site-packages/flask/app.py", line 2449, in wsgi_app
    response = self.handle_exception(e)
  File "/usr/local/lib64/python3.6/site-packages/flask_cors/extension.py", line 161, in wrapped_function
    return cors_after_request(app.make_response(f(*args, **kwargs)))
  File "/usr/local/lib/python3.6/site-packages/flask/app.py", line 1866, in handle_exception
    reraise(exc_type, exc_value, tb)
  File "/usr/local/lib/python3.6/site-packages/flask/_compat.py", line 39, in reraise
    raise value
  File "/usr/local/lib/python3.6/site-packages/flask/app.py", line 2446, in wsgi_app
    response = self.full_dispatch_request()
  File "/usr/local/lib/python3.6/site-packages/flask/app.py", line 1951, in full_dispatch_request
    rv = self.handle_user_exception(e)
  File "/usr/local/lib64/python3.6/site-packages/flask_cors/extension.py", line 161, in wrapped_function
    return cors_after_request(app.make_response(f(*args, **kwargs)))
  File "/usr/local/lib/python3.6/site-packages/flask/app.py", line 1820, in handle_user_exception
    reraise(exc_type, exc_value, tb)
  File "/usr/local/lib/python3.6/site-packages/flask/_compat.py", line 39, in reraise
    raise value
  File "/usr/local/lib/python3.6/site-packages/flask/app.py", line 1949, in full_dispatch_request
    rv = self.dispatch_request()
  File "/usr/local/lib/python3.6/site-packages/flask/app.py", line 1935, in dispatch_request
    return self.view_functions[rule.endpoint](**req.view_args)
  File "/home/et/backend_server/app/utils/auth.py", line 143, in wrapper
    return f(*args, **kwargs)
  File "/home/et/backend_server/app/api/oem_service.py", line 75, in registered
    user = db.session.query(EtAccount).filter(EtAccount.name == username).first()
  File "/usr/local/lib/python3.6/site-packages/sqlalchemy/orm/query.py", line 3215, in first
    ret = list(self[0:1])
  File "/usr/local/lib/python3.6/site-packages/sqlalchemy/orm/query.py", line 3007, in __getitem__
    return list(res)
  File "/usr/local/lib/python3.6/site-packages/sqlalchemy/orm/query.py", line 3317, in __iter__
    return self._execute_and_instances(context)
  File "/usr/local/lib/python3.6/site-packages/sqlalchemy/orm/query.py", line 3342, in _execute_and_instances
    result = conn.execute(querycontext.statement, self._params)
  File "/usr/local/lib/python3.6/site-packages/sqlalchemy/engine/base.py", line 988, in execute
    return meth(self, multiparams, params)
  File "/usr/local/lib/python3.6/site-packages/sqlalchemy/sql/elements.py", line 287, in _execute_on_connection
    return connection._execute_clauseelement(self, multiparams, params)
  File "/usr/local/lib/python3.6/site-packages/sqlalchemy/engine/base.py", line 1107, in _execute_clauseelement
    distilled_params,
  File "/usr/local/lib/python3.6/site-packages/sqlalchemy/engine/base.py", line 1248, in _execute_context
    e, statement, parameters, cursor, context
  File "/usr/local/lib/python3.6/site-packages/sqlalchemy/engine/base.py", line 1466, in _handle_dbapi_exception
    util.raise_from_cause(sqlalchemy_exception, exc_info)
  File "/usr/local/lib/python3.6/site-packages/sqlalchemy/util/compat.py", line 383, in raise_from_cause
    reraise(type(exception), exception, tb=exc_tb, cause=cause)
  File "/usr/local/lib/python3.6/site-packages/sqlalchemy/util/compat.py", line 128, in reraise
    raise value.with_traceback(tb)
  File "/usr/local/lib/python3.6/site-packages/sqlalchemy/engine/base.py", line 1244, in _execute_context
    cursor, statement, parameters, context
  File "/usr/local/lib/python3.6/site-packages/sqlalchemy/engine/default.py", line 552, in do_execute
    cursor.execute(statement, parameters)
  File "/usr/local/lib64/python3.6/site-packages/elasticapm/instrumentation/packages/dbapi2.py", line 209, in execute
    return self._trace_sql(self.__wrapped__.execute, sql, params)
  File "/usr/local/lib64/python3.6/site-packages/elasticapm/instrumentation/packages/dbapi2.py", line 238, in _trace_sql
    return method(sql, params)
  File "/usr/local/lib/python3.6/site-packages/pymysql/cursors.py", line 170, in execute
    result = self._query(query)
  File "/usr/local/lib/python3.6/site-packages/pymysql/cursors.py", line 328, in _query
    conn.query(q)
  File "/usr/local/lib/python3.6/site-packages/pymysql/connections.py", line 516, in query
    self._affected_rows = self._read_query_result(unbuffered=unbuffered)
  File "/usr/local/lib/python3.6/site-packages/pymysql/connections.py", line 727, in _read_query_result
    result.read()
  File "/usr/local/lib/python3.6/site-packages/pymysql/connections.py", line 1066, in read
    first_packet = self.connection._read_packet()
  File "/usr/local/lib/python3.6/site-packages/pymysql/connections.py", line 683, in _read_packet
    packet.check_error()
  File "/usr/local/lib/python3.6/site-packages/pymysql/protocol.py", line 220, in check_error
    err.raise_mysql_exception(self._data)
  File "/usr/local/lib/python3.6/site-packages/pymysql/err.py", line 109, in raise_mysql_exception
    raise errorclass(errno, errval)
sqlalchemy.exc.InternalError: (pymysql.err.InternalError) (1054, "Unknown column 'et_accounts.mobile' in 'field list'")
[SQL: SELECT et_accounts.id AS et_accounts_id, et_accounts.name AS et_accounts_name, et_accounts.password AS et_accounts_password, et_accounts.mobile AS et_accounts_mobile, et_accounts.role_id AS et_accounts_role_id, et_accounts.status AS et_accounts_status, et_accounts.add_time AS et_accounts_add_time, et_accounts.last_login AS et_accounts_last_login, et_accounts.ip AS et_accounts_ip 
FROM et_accounts 
WHERE et_accounts.name = %(name_1)s 
 LIMIT %(param_1)s]
[parameters: {'name_1': '牛逼', 'param_1': 1}]
(Background on this error at: http://sqlalche.me/e/2j85)
18
99
[2020-05-07 10:51:44 +0800] [29870] [ERROR] Error handling request /account/login
Traceback (most recent call last):
  File "/usr/local/lib/python3.6/site-packages/sqlalchemy/engine/base.py", line 1244, in _execute_context
    cursor, statement, parameters, context
  File "/usr/local/lib/python3.6/site-packages/sqlalchemy/engine/default.py", line 552, in do_execute
    cursor.execute(statement, parameters)
  File "/usr/local/lib64/python3.6/site-packages/elasticapm/instrumentation/packages/dbapi2.py", line 209, in execute
    return self._trace_sql(self.__wrapped__.execute, sql, params)
  File "/usr/local/lib64/python3.6/site-packages/elasticapm/instrumentation/packages/dbapi2.py", line 238, in _trace_sql
    return method(sql, params)
  File "/usr/local/lib/python3.6/site-packages/pymysql/cursors.py", line 170, in execute
    result = self._query(query)
  File "/usr/local/lib/python3.6/site-packages/pymysql/cursors.py", line 328, in _query
    conn.query(q)
  File "/usr/local/lib/python3.6/site-packages/pymysql/connections.py", line 516, in query
    self._affected_rows = self._read_query_result(unbuffered=unbuffered)
  File "/usr/local/lib/python3.6/site-packages/pymysql/connections.py", line 727, in _read_query_result
    result.read()
  File "/usr/local/lib/python3.6/site-packages/pymysql/connections.py", line 1066, in read
    first_packet = self.connection._read_packet()
  File "/usr/local/lib/python3.6/site-packages/pymysql/connections.py", line 683, in _read_packet
    packet.check_error()
  File "/usr/local/lib/python3.6/site-packages/pymysql/protocol.py", line 220, in check_error
    err.raise_mysql_exception(self._data)
  File "/usr/local/lib/python3.6/site-packages/pymysql/err.py", line 109, in raise_mysql_exception
    raise errorclass(errno, errval)
pymysql.err.InternalError: (1054, "Unknown column 'et_accounts.mobile' in 'field list'")

The above exception was the direct cause of the following exception:

Traceback (most recent call last):
  File "/usr/local/lib/python3.6/site-packages/gunicorn/workers/base_async.py", line 55, in handle
    self.handle_request(listener_name, req, client, addr)
  File "/usr/local/lib/python3.6/site-packages/gunicorn/workers/base_async.py", line 106, in handle_request
    respiter = self.wsgi(environ, resp.start_response)
  File "/usr/local/lib/python3.6/site-packages/flask/app.py", line 2463, in __call__
    return self.wsgi_app(environ, start_response)
  File "/usr/local/lib/python3.6/site-packages/flask/app.py", line 2449, in wsgi_app
    response = self.handle_exception(e)
  File "/usr/local/lib64/python3.6/site-packages/flask_cors/extension.py", line 161, in wrapped_function
    return cors_after_request(app.make_response(f(*args, **kwargs)))
  File "/usr/local/lib/python3.6/site-packages/flask/app.py", line 1866, in handle_exception
    reraise(exc_type, exc_value, tb)
  File "/usr/local/lib/python3.6/site-packages/flask/_compat.py", line 39, in reraise
    raise value
  File "/usr/local/lib/python3.6/site-packages/flask/app.py", line 2446, in wsgi_app
    response = self.full_dispatch_request()
  File "/usr/local/lib/python3.6/site-packages/flask/app.py", line 1951, in full_dispatch_request
    rv = self.handle_user_exception(e)
  File "/usr/local/lib64/python3.6/site-packages/flask_cors/extension.py", line 161, in wrapped_function
    return cors_after_request(app.make_response(f(*args, **kwargs)))
  File "/usr/local/lib/python3.6/site-packages/flask/app.py", line 1820, in handle_user_exception
    reraise(exc_type, exc_value, tb)
  File "/usr/local/lib/python3.6/site-packages/flask/_compat.py", line 39, in reraise
    raise value
  File "/usr/local/lib/python3.6/site-packages/flask/app.py", line 1949, in full_dispatch_request
    rv = self.dispatch_request()
  File "/usr/local/lib/python3.6/site-packages/flask/app.py", line 1935, in dispatch_request
    return self.view_functions[rule.endpoint](**req.view_args)
  File "/home/et/backend_server/app/utils/util.py", line 110, in wrapper
    rv = f(*args, **kwargs)
  File "/home/et/backend_server/app/api/account_service.py", line 120, in handle_login
    EtAccount.password==password_hash).first()
  File "/usr/local/lib/python3.6/site-packages/sqlalchemy/orm/query.py", line 3215, in first
    ret = list(self[0:1])
  File "/usr/local/lib/python3.6/site-packages/sqlalchemy/orm/query.py", line 3007, in __getitem__
    return list(res)
  File "/usr/local/lib/python3.6/site-packages/sqlalchemy/orm/query.py", line 3317, in __iter__
    return self._execute_and_instances(context)
  File "/usr/local/lib/python3.6/site-packages/sqlalchemy/orm/query.py", line 3342, in _execute_and_instances
    result = conn.execute(querycontext.statement, self._params)
  File "/usr/local/lib/python3.6/site-packages/sqlalchemy/engine/base.py", line 988, in execute
    return meth(self, multiparams, params)
  File "/usr/local/lib/python3.6/site-packages/sqlalchemy/sql/elements.py", line 287, in _execute_on_connection
    return connection._execute_clauseelement(self, multiparams, params)
  File "/usr/local/lib/python3.6/site-packages/sqlalchemy/engine/base.py", line 1107, in _execute_clauseelement
    distilled_params,
  File "/usr/local/lib/python3.6/site-packages/sqlalchemy/engine/base.py", line 1248, in _execute_context
    e, statement, parameters, cursor, context
  File "/usr/local/lib/python3.6/site-packages/sqlalchemy/engine/base.py", line 1466, in _handle_dbapi_exception
    util.raise_from_cause(sqlalchemy_exception, exc_info)
  File "/usr/local/lib/python3.6/site-packages/sqlalchemy/util/compat.py", line 383, in raise_from_cause
    reraise(type(exception), exception, tb=exc_tb, cause=cause)
  File "/usr/local/lib/python3.6/site-packages/sqlalchemy/util/compat.py", line 128, in reraise
    raise value.with_traceback(tb)
  File "/usr/local/lib/python3.6/site-packages/sqlalchemy/engine/base.py", line 1244, in _execute_context
    cursor, statement, parameters, context
  File "/usr/local/lib/python3.6/site-packages/sqlalchemy/engine/default.py", line 552, in do_execute
    cursor.execute(statement, parameters)
  File "/usr/local/lib64/python3.6/site-packages/elasticapm/instrumentation/packages/dbapi2.py", line 209, in execute
    return self._trace_sql(self.__wrapped__.execute, sql, params)
  File "/usr/local/lib64/python3.6/site-packages/elasticapm/instrumentation/packages/dbapi2.py", line 238, in _trace_sql
    return method(sql, params)
  File "/usr/local/lib/python3.6/site-packages/pymysql/cursors.py", line 170, in execute
    result = self._query(query)
  File "/usr/local/lib/python3.6/site-packages/pymysql/cursors.py", line 328, in _query
    conn.query(q)
  File "/usr/local/lib/python3.6/site-packages/pymysql/connections.py", line 516, in query
    self._affected_rows = self._read_query_result(unbuffered=unbuffered)
  File "/usr/local/lib/python3.6/site-packages/pymysql/connections.py", line 727, in _read_query_result
    result.read()
  File "/usr/local/lib/python3.6/site-packages/pymysql/connections.py", line 1066, in read
    first_packet = self.connection._read_packet()
  File "/usr/local/lib/python3.6/site-packages/pymysql/connections.py", line 683, in _read_packet
    packet.check_error()
  File "/usr/local/lib/python3.6/site-packages/pymysql/protocol.py", line 220, in check_error
    err.raise_mysql_exception(self._data)
  File "/usr/local/lib/python3.6/site-packages/pymysql/err.py", line 109, in raise_mysql_exception
    raise errorclass(errno, errval)
sqlalchemy.exc.InternalError: (pymysql.err.InternalError) (1054, "Unknown column 'et_accounts.mobile' in 'field list'")
[SQL: SELECT et_accounts.id AS et_accounts_id, et_accounts.name AS et_accounts_name, et_accounts.password AS et_accounts_password, et_accounts.mobile AS et_accounts_mobile, et_accounts.role_id AS et_accounts_role_id, et_accounts.status AS et_accounts_status, et_accounts.add_time AS et_accounts_add_time, et_accounts.last_login AS et_accounts_last_login, et_accounts.ip AS et_accounts_ip 
FROM et_accounts 
WHERE et_accounts.name = %(name_1)s AND et_accounts.password = %(password_1)s 
 LIMIT %(param_1)s]
[parameters: {'name_1': 'admin', 'password_1': '54d50ca4a93ea84ad048a2aba899a9d9', 'param_1': 1}]
(Background on this error at: http://sqlalche.me/e/2j85)
[2020-05-07 10:52:53 +0800] [29870] [ERROR] Error handling request /account/login
Traceback (most recent call last):
  File "/usr/local/lib/python3.6/site-packages/sqlalchemy/engine/base.py", line 1244, in _execute_context
    cursor, statement, parameters, context
  File "/usr/local/lib/python3.6/site-packages/sqlalchemy/engine/default.py", line 552, in do_execute
    cursor.execute(statement, parameters)
  File "/usr/local/lib64/python3.6/site-packages/elasticapm/instrumentation/packages/dbapi2.py", line 209, in execute
    return self._trace_sql(self.__wrapped__.execute, sql, params)
  File "/usr/local/lib64/python3.6/site-packages/elasticapm/instrumentation/packages/dbapi2.py", line 238, in _trace_sql
    return method(sql, params)
  File "/usr/local/lib/python3.6/site-packages/pymysql/cursors.py", line 170, in execute
    result = self._query(query)
  File "/usr/local/lib/python3.6/site-packages/pymysql/cursors.py", line 328, in _query
    conn.query(q)
  File "/usr/local/lib/python3.6/site-packages/pymysql/connections.py", line 516, in query
    self._affected_rows = self._read_query_result(unbuffered=unbuffered)
  File "/usr/local/lib/python3.6/site-packages/pymysql/connections.py", line 727, in _read_query_result
    result.read()
  File "/usr/local/lib/python3.6/site-packages/pymysql/connections.py", line 1066, in read
    first_packet = self.connection._read_packet()
  File "/usr/local/lib/python3.6/site-packages/pymysql/connections.py", line 683, in _read_packet
    packet.check_error()
  File "/usr/local/lib/python3.6/site-packages/pymysql/protocol.py", line 220, in check_error
    err.raise_mysql_exception(self._data)
  File "/usr/local/lib/python3.6/site-packages/pymysql/err.py", line 109, in raise_mysql_exception
    raise errorclass(errno, errval)
pymysql.err.InternalError: (1054, "Unknown column 'et_accounts.mobile' in 'field list'")

The above exception was the direct cause of the following exception:

Traceback (most recent call last):
  File "/usr/local/lib/python3.6/site-packages/gunicorn/workers/base_async.py", line 55, in handle
    self.handle_request(listener_name, req, client, addr)
  File "/usr/local/lib/python3.6/site-packages/gunicorn/workers/base_async.py", line 106, in handle_request
    respiter = self.wsgi(environ, resp.start_response)
  File "/usr/local/lib/python3.6/site-packages/flask/app.py", line 2463, in __call__
    return self.wsgi_app(environ, start_response)
  File "/usr/local/lib/python3.6/site-packages/flask/app.py", line 2449, in wsgi_app
    response = self.handle_exception(e)
  File "/usr/local/lib64/python3.6/site-packages/flask_cors/extension.py", line 161, in wrapped_function
    return cors_after_request(app.make_response(f(*args, **kwargs)))
  File "/usr/local/lib/python3.6/site-packages/flask/app.py", line 1866, in handle_exception
    reraise(exc_type, exc_value, tb)
  File "/usr/local/lib/python3.6/site-packages/flask/_compat.py", line 39, in reraise
    raise value
  File "/usr/local/lib/python3.6/site-packages/flask/app.py", line 2446, in wsgi_app
    response = self.full_dispatch_request()
  File "/usr/local/lib/python3.6/site-packages/flask/app.py", line 1951, in full_dispatch_request
    rv = self.handle_user_exception(e)
  File "/usr/local/lib64/python3.6/site-packages/flask_cors/extension.py", line 161, in wrapped_function
    return cors_after_request(app.make_response(f(*args, **kwargs)))
  File "/usr/local/lib/python3.6/site-packages/flask/app.py", line 1820, in handle_user_exception
    reraise(exc_type, exc_value, tb)
  File "/usr/local/lib/python3.6/site-packages/flask/_compat.py", line 39, in reraise
    raise value
  File "/usr/local/lib/python3.6/site-packages/flask/app.py", line 1949, in full_dispatch_request
    rv = self.dispatch_request()
  File "/usr/local/lib/python3.6/site-packages/flask/app.py", line 1935, in dispatch_request
    return self.view_functions[rule.endpoint](**req.view_args)
  File "/home/et/backend_server/app/utils/util.py", line 110, in wrapper
    rv = f(*args, **kwargs)
  File "/home/et/backend_server/app/api/account_service.py", line 120, in handle_login
    EtAccount.password==password_hash).first()
  File "/usr/local/lib/python3.6/site-packages/sqlalchemy/orm/query.py", line 3215, in first
    ret = list(self[0:1])
  File "/usr/local/lib/python3.6/site-packages/sqlalchemy/orm/query.py", line 3007, in __getitem__
    return list(res)
  File "/usr/local/lib/python3.6/site-packages/sqlalchemy/orm/query.py", line 3317, in __iter__
    return self._execute_and_instances(context)
  File "/usr/local/lib/python3.6/site-packages/sqlalchemy/orm/query.py", line 3342, in _execute_and_instances
    result = conn.execute(querycontext.statement, self._params)
  File "/usr/local/lib/python3.6/site-packages/sqlalchemy/engine/base.py", line 988, in execute
    return meth(self, multiparams, params)
  File "/usr/local/lib/python3.6/site-packages/sqlalchemy/sql/elements.py", line 287, in _execute_on_connection
    return connection._execute_clauseelement(self, multiparams, params)
  File "/usr/local/lib/python3.6/site-packages/sqlalchemy/engine/base.py", line 1107, in _execute_clauseelement
    distilled_params,
  File "/usr/local/lib/python3.6/site-packages/sqlalchemy/engine/base.py", line 1248, in _execute_context
    e, statement, parameters, cursor, context
  File "/usr/local/lib/python3.6/site-packages/sqlalchemy/engine/base.py", line 1466, in _handle_dbapi_exception
    util.raise_from_cause(sqlalchemy_exception, exc_info)
  File "/usr/local/lib/python3.6/site-packages/sqlalchemy/util/compat.py", line 383, in raise_from_cause
    reraise(type(exception), exception, tb=exc_tb, cause=cause)
  File "/usr/local/lib/python3.6/site-packages/sqlalchemy/util/compat.py", line 128, in reraise
    raise value.with_traceback(tb)
  File "/usr/local/lib/python3.6/site-packages/sqlalchemy/engine/base.py", line 1244, in _execute_context
    cursor, statement, parameters, context
  File "/usr/local/lib/python3.6/site-packages/sqlalchemy/engine/default.py", line 552, in do_execute
    cursor.execute(statement, parameters)
  File "/usr/local/lib64/python3.6/site-packages/elasticapm/instrumentation/packages/dbapi2.py", line 209, in execute
    return self._trace_sql(self.__wrapped__.execute, sql, params)
  File "/usr/local/lib64/python3.6/site-packages/elasticapm/instrumentation/packages/dbapi2.py", line 238, in _trace_sql
    return method(sql, params)
  File "/usr/local/lib/python3.6/site-packages/pymysql/cursors.py", line 170, in execute
    result = self._query(query)
  File "/usr/local/lib/python3.6/site-packages/pymysql/cursors.py", line 328, in _query
    conn.query(q)
  File "/usr/local/lib/python3.6/site-packages/pymysql/connections.py", line 516, in query
    self._affected_rows = self._read_query_result(unbuffered=unbuffered)
  File "/usr/local/lib/python3.6/site-packages/pymysql/connections.py", line 727, in _read_query_result
    result.read()
  File "/usr/local/lib/python3.6/site-packages/pymysql/connections.py", line 1066, in read
    first_packet = self.connection._read_packet()
  File "/usr/local/lib/python3.6/site-packages/pymysql/connections.py", line 683, in _read_packet
    packet.check_error()
  File "/usr/local/lib/python3.6/site-packages/pymysql/protocol.py", line 220, in check_error
    err.raise_mysql_exception(self._data)
  File "/usr/local/lib/python3.6/site-packages/pymysql/err.py", line 109, in raise_mysql_exception
    raise errorclass(errno, errval)
sqlalchemy.exc.InternalError: (pymysql.err.InternalError) (1054, "Unknown column 'et_accounts.mobile' in 'field list'")
[SQL: SELECT et_accounts.id AS et_accounts_id, et_accounts.name AS et_accounts_name, et_accounts.password AS et_accounts_password, et_accounts.mobile AS et_accounts_mobile, et_accounts.role_id AS et_accounts_role_id, et_accounts.status AS et_accounts_status, et_accounts.add_time AS et_accounts_add_time, et_accounts.last_login AS et_accounts_last_login, et_accounts.ip AS et_accounts_ip 
FROM et_accounts 
WHERE et_accounts.name = %(name_1)s AND et_accounts.password = %(password_1)s 
 LIMIT %(param_1)s]
[parameters: {'name_1': 'admin', 'password_1': '54d50ca4a93ea84ad048a2aba899a9d9', 'param_1': 1}]
(Background on this error at: http://sqlalche.me/e/2j85)
[2020-05-07 10:55:17 +0800] [29870] [INFO] Worker reloading: /home/et/backend_server/app/models/accounts.py modified
[2020-05-07 10:55:17 +0800] [29869] [INFO] Worker reloading: /home/et/backend_server/app/models/accounts.py modified
[2020-05-07 10:55:17 +0800] [29870] [INFO] Worker exiting (pid: 29870)
[2020-05-07 10:55:17 +0800] [29869] [INFO] Worker exiting (pid: 29869)
[2020-05-07 10:55:17 +0800] [2175] [INFO] Booting worker with pid: 2175
[2020-05-07 10:55:17 +0800] [2176] [INFO] Booting worker with pid: 2176
[2020-05-07 10:56:21 +0800] [2176] [INFO] Worker reloading: /home/et/backend_server/app/api/oem_service.py modified
[2020-05-07 10:56:21 +0800] [2176] [INFO] Worker exiting (pid: 2176)
[2020-05-07 10:56:21 +0800] [2175] [INFO] Worker reloading: /home/et/backend_server/app/api/oem_service.py modified
[2020-05-07 10:56:21 +0800] [2175] [INFO] Worker exiting (pid: 2175)
[2020-05-07 10:56:22 +0800] [2675] [INFO] Booting worker with pid: 2675
[2020-05-07 10:56:22 +0800] [2676] [INFO] Booting worker with pid: 2676
[2020-05-07 10:56:36 +0800] [2676] [ERROR] Error handling request /account/login
Traceback (most recent call last):
  File "/usr/local/lib/python3.6/site-packages/sqlalchemy/engine/base.py", line 1244, in _execute_context
    cursor, statement, parameters, context
  File "/usr/local/lib/python3.6/site-packages/sqlalchemy/engine/default.py", line 552, in do_execute
    cursor.execute(statement, parameters)
  File "/usr/local/lib64/python3.6/site-packages/elasticapm/instrumentation/packages/dbapi2.py", line 209, in execute
    return self._trace_sql(self.__wrapped__.execute, sql, params)
  File "/usr/local/lib64/python3.6/site-packages/elasticapm/instrumentation/packages/dbapi2.py", line 238, in _trace_sql
    return method(sql, params)
  File "/usr/local/lib/python3.6/site-packages/pymysql/cursors.py", line 170, in execute
    result = self._query(query)
  File "/usr/local/lib/python3.6/site-packages/pymysql/cursors.py", line 328, in _query
    conn.query(q)
  File "/usr/local/lib/python3.6/site-packages/pymysql/connections.py", line 516, in query
    self._affected_rows = self._read_query_result(unbuffered=unbuffered)
  File "/usr/local/lib/python3.6/site-packages/pymysql/connections.py", line 727, in _read_query_result
    result.read()
  File "/usr/local/lib/python3.6/site-packages/pymysql/connections.py", line 1066, in read
    first_packet = self.connection._read_packet()
  File "/usr/local/lib/python3.6/site-packages/pymysql/connections.py", line 683, in _read_packet
    packet.check_error()
  File "/usr/local/lib/python3.6/site-packages/pymysql/protocol.py", line 220, in check_error
    err.raise_mysql_exception(self._data)
  File "/usr/local/lib/python3.6/site-packages/pymysql/err.py", line 109, in raise_mysql_exception
    raise errorclass(errno, errval)
pymysql.err.InternalError: (1054, "Unknown column 'et_accounts.mobile' in 'field list'")

The above exception was the direct cause of the following exception:

Traceback (most recent call last):
  File "/usr/local/lib/python3.6/site-packages/gunicorn/workers/base_async.py", line 55, in handle
    self.handle_request(listener_name, req, client, addr)
  File "/usr/local/lib/python3.6/site-packages/gunicorn/workers/base_async.py", line 106, in handle_request
    respiter = self.wsgi(environ, resp.start_response)
  File "/usr/local/lib/python3.6/site-packages/flask/app.py", line 2463, in __call__
    return self.wsgi_app(environ, start_response)
  File "/usr/local/lib/python3.6/site-packages/flask/app.py", line 2449, in wsgi_app
    response = self.handle_exception(e)
  File "/usr/local/lib64/python3.6/site-packages/flask_cors/extension.py", line 161, in wrapped_function
    return cors_after_request(app.make_response(f(*args, **kwargs)))
  File "/usr/local/lib/python3.6/site-packages/flask/app.py", line 1866, in handle_exception
    reraise(exc_type, exc_value, tb)
  File "/usr/local/lib/python3.6/site-packages/flask/_compat.py", line 39, in reraise
    raise value
  File "/usr/local/lib/python3.6/site-packages/flask/app.py", line 2446, in wsgi_app
    response = self.full_dispatch_request()
  File "/usr/local/lib/python3.6/site-packages/flask/app.py", line 1951, in full_dispatch_request
    rv = self.handle_user_exception(e)
  File "/usr/local/lib64/python3.6/site-packages/flask_cors/extension.py", line 161, in wrapped_function
    return cors_after_request(app.make_response(f(*args, **kwargs)))
  File "/usr/local/lib/python3.6/site-packages/flask/app.py", line 1820, in handle_user_exception
    reraise(exc_type, exc_value, tb)
  File "/usr/local/lib/python3.6/site-packages/flask/_compat.py", line 39, in reraise
    raise value
  File "/usr/local/lib/python3.6/site-packages/flask/app.py", line 1949, in full_dispatch_request
    rv = self.dispatch_request()
  File "/usr/local/lib/python3.6/site-packages/flask/app.py", line 1935, in dispatch_request
    return self.view_functions[rule.endpoint](**req.view_args)
  File "/home/et/backend_server/app/utils/util.py", line 110, in wrapper
    rv = f(*args, **kwargs)
  File "/home/et/backend_server/app/api/account_service.py", line 120, in handle_login
    EtAccount.password==password_hash).first()
  File "/usr/local/lib/python3.6/site-packages/sqlalchemy/orm/query.py", line 3215, in first
    ret = list(self[0:1])
  File "/usr/local/lib/python3.6/site-packages/sqlalchemy/orm/query.py", line 3007, in __getitem__
    return list(res)
  File "/usr/local/lib/python3.6/site-packages/sqlalchemy/orm/query.py", line 3317, in __iter__
    return self._execute_and_instances(context)
  File "/usr/local/lib/python3.6/site-packages/sqlalchemy/orm/query.py", line 3342, in _execute_and_instances
    result = conn.execute(querycontext.statement, self._params)
  File "/usr/local/lib/python3.6/site-packages/sqlalchemy/engine/base.py", line 988, in execute
    return meth(self, multiparams, params)
  File "/usr/local/lib/python3.6/site-packages/sqlalchemy/sql/elements.py", line 287, in _execute_on_connection
    return connection._execute_clauseelement(self, multiparams, params)
  File "/usr/local/lib/python3.6/site-packages/sqlalchemy/engine/base.py", line 1107, in _execute_clauseelement
    distilled_params,
  File "/usr/local/lib/python3.6/site-packages/sqlalchemy/engine/base.py", line 1248, in _execute_context
    e, statement, parameters, cursor, context
  File "/usr/local/lib/python3.6/site-packages/sqlalchemy/engine/base.py", line 1466, in _handle_dbapi_exception
    util.raise_from_cause(sqlalchemy_exception, exc_info)
  File "/usr/local/lib/python3.6/site-packages/sqlalchemy/util/compat.py", line 383, in raise_from_cause
    reraise(type(exception), exception, tb=exc_tb, cause=cause)
  File "/usr/local/lib/python3.6/site-packages/sqlalchemy/util/compat.py", line 128, in reraise
    raise value.with_traceback(tb)
  File "/usr/local/lib/python3.6/site-packages/sqlalchemy/engine/base.py", line 1244, in _execute_context
    cursor, statement, parameters, context
  File "/usr/local/lib/python3.6/site-packages/sqlalchemy/engine/default.py", line 552, in do_execute
    cursor.execute(statement, parameters)
  File "/usr/local/lib64/python3.6/site-packages/elasticapm/instrumentation/packages/dbapi2.py", line 209, in execute
    return self._trace_sql(self.__wrapped__.execute, sql, params)
  File "/usr/local/lib64/python3.6/site-packages/elasticapm/instrumentation/packages/dbapi2.py", line 238, in _trace_sql
    return method(sql, params)
  File "/usr/local/lib/python3.6/site-packages/pymysql/cursors.py", line 170, in execute
    result = self._query(query)
  File "/usr/local/lib/python3.6/site-packages/pymysql/cursors.py", line 328, in _query
    conn.query(q)
  File "/usr/local/lib/python3.6/site-packages/pymysql/connections.py", line 516, in query
    self._affected_rows = self._read_query_result(unbuffered=unbuffered)
  File "/usr/local/lib/python3.6/site-packages/pymysql/connections.py", line 727, in _read_query_result
    result.read()
  File "/usr/local/lib/python3.6/site-packages/pymysql/connections.py", line 1066, in read
    first_packet = self.connection._read_packet()
  File "/usr/local/lib/python3.6/site-packages/pymysql/connections.py", line 683, in _read_packet
    packet.check_error()
  File "/usr/local/lib/python3.6/site-packages/pymysql/protocol.py", line 220, in check_error
    err.raise_mysql_exception(self._data)
  File "/usr/local/lib/python3.6/site-packages/pymysql/err.py", line 109, in raise_mysql_exception
    raise errorclass(errno, errval)
sqlalchemy.exc.InternalError: (pymysql.err.InternalError) (1054, "Unknown column 'et_accounts.mobile' in 'field list'")
[SQL: SELECT et_accounts.id AS et_accounts_id, et_accounts.name AS et_accounts_name, et_accounts.password AS et_accounts_password, et_accounts.mobile AS et_accounts_mobile, et_accounts.role_id AS et_accounts_role_id, et_accounts.status AS et_accounts_status, et_accounts.add_time AS et_accounts_add_time, et_accounts.last_login AS et_accounts_last_login, et_accounts.ip AS et_accounts_ip 
FROM et_accounts 
WHERE et_accounts.name = %(name_1)s AND et_accounts.password = %(password_1)s 
 LIMIT %(param_1)s]
[parameters: {'name_1': 'admin', 'password_1': '54d50ca4a93ea84ad048a2aba899a9d9', 'param_1': 1}]
(Background on this error at: http://sqlalche.me/e/2j85)
[2020-05-07 10:57:05 +0800] [2675] [ERROR] Error handling request /account/login
Traceback (most recent call last):
  File "/usr/local/lib/python3.6/site-packages/sqlalchemy/engine/base.py", line 1244, in _execute_context
    cursor, statement, parameters, context
  File "/usr/local/lib/python3.6/site-packages/sqlalchemy/engine/default.py", line 552, in do_execute
    cursor.execute(statement, parameters)
  File "/usr/local/lib64/python3.6/site-packages/elasticapm/instrumentation/packages/dbapi2.py", line 209, in execute
    return self._trace_sql(self.__wrapped__.execute, sql, params)
  File "/usr/local/lib64/python3.6/site-packages/elasticapm/instrumentation/packages/dbapi2.py", line 238, in _trace_sql
    return method(sql, params)
  File "/usr/local/lib/python3.6/site-packages/pymysql/cursors.py", line 170, in execute
    result = self._query(query)
  File "/usr/local/lib/python3.6/site-packages/pymysql/cursors.py", line 328, in _query
    conn.query(q)
  File "/usr/local/lib/python3.6/site-packages/pymysql/connections.py", line 516, in query
    self._affected_rows = self._read_query_result(unbuffered=unbuffered)
  File "/usr/local/lib/python3.6/site-packages/pymysql/connections.py", line 727, in _read_query_result
    result.read()
  File "/usr/local/lib/python3.6/site-packages/pymysql/connections.py", line 1066, in read
    first_packet = self.connection._read_packet()
  File "/usr/local/lib/python3.6/site-packages/pymysql/connections.py", line 683, in _read_packet
    packet.check_error()
  File "/usr/local/lib/python3.6/site-packages/pymysql/protocol.py", line 220, in check_error
    err.raise_mysql_exception(self._data)
  File "/usr/local/lib/python3.6/site-packages/pymysql/err.py", line 109, in raise_mysql_exception
    raise errorclass(errno, errval)
pymysql.err.InternalError: (1054, "Unknown column 'et_accounts.mobile' in 'field list'")

The above exception was the direct cause of the following exception:

Traceback (most recent call last):
  File "/usr/local/lib/python3.6/site-packages/gunicorn/workers/base_async.py", line 55, in handle
    self.handle_request(listener_name, req, client, addr)
  File "/usr/local/lib/python3.6/site-packages/gunicorn/workers/base_async.py", line 106, in handle_request
    respiter = self.wsgi(environ, resp.start_response)
  File "/usr/local/lib/python3.6/site-packages/flask/app.py", line 2463, in __call__
    return self.wsgi_app(environ, start_response)
  File "/usr/local/lib/python3.6/site-packages/flask/app.py", line 2449, in wsgi_app
    response = self.handle_exception(e)
  File "/usr/local/lib64/python3.6/site-packages/flask_cors/extension.py", line 161, in wrapped_function
    return cors_after_request(app.make_response(f(*args, **kwargs)))
  File "/usr/local/lib/python3.6/site-packages/flask/app.py", line 1866, in handle_exception
    reraise(exc_type, exc_value, tb)
  File "/usr/local/lib/python3.6/site-packages/flask/_compat.py", line 39, in reraise
    raise value
  File "/usr/local/lib/python3.6/site-packages/flask/app.py", line 2446, in wsgi_app
    response = self.full_dispatch_request()
  File "/usr/local/lib/python3.6/site-packages/flask/app.py", line 1951, in full_dispatch_request
    rv = self.handle_user_exception(e)
  File "/usr/local/lib64/python3.6/site-packages/flask_cors/extension.py", line 161, in wrapped_function
    return cors_after_request(app.make_response(f(*args, **kwargs)))
  File "/usr/local/lib/python3.6/site-packages/flask/app.py", line 1820, in handle_user_exception
    reraise(exc_type, exc_value, tb)
  File "/usr/local/lib/python3.6/site-packages/flask/_compat.py", line 39, in reraise
    raise value
  File "/usr/local/lib/python3.6/site-packages/flask/app.py", line 1949, in full_dispatch_request
    rv = self.dispatch_request()
  File "/usr/local/lib/python3.6/site-packages/flask/app.py", line 1935, in dispatch_request
    return self.view_functions[rule.endpoint](**req.view_args)
  File "/home/et/backend_server/app/utils/util.py", line 110, in wrapper
    rv = f(*args, **kwargs)
  File "/home/et/backend_server/app/api/account_service.py", line 120, in handle_login
    EtAccount.password==password_hash).first()
  File "/usr/local/lib/python3.6/site-packages/sqlalchemy/orm/query.py", line 3215, in first
    ret = list(self[0:1])
  File "/usr/local/lib/python3.6/site-packages/sqlalchemy/orm/query.py", line 3007, in __getitem__
    return list(res)
  File "/usr/local/lib/python3.6/site-packages/sqlalchemy/orm/query.py", line 3317, in __iter__
    return self._execute_and_instances(context)
  File "/usr/local/lib/python3.6/site-packages/sqlalchemy/orm/query.py", line 3342, in _execute_and_instances
    result = conn.execute(querycontext.statement, self._params)
  File "/usr/local/lib/python3.6/site-packages/sqlalchemy/engine/base.py", line 988, in execute
    return meth(self, multiparams, params)
  File "/usr/local/lib/python3.6/site-packages/sqlalchemy/sql/elements.py", line 287, in _execute_on_connection
    return connection._execute_clauseelement(self, multiparams, params)
  File "/usr/local/lib/python3.6/site-packages/sqlalchemy/engine/base.py", line 1107, in _execute_clauseelement
    distilled_params,
  File "/usr/local/lib/python3.6/site-packages/sqlalchemy/engine/base.py", line 1248, in _execute_context
    e, statement, parameters, cursor, context
  File "/usr/local/lib/python3.6/site-packages/sqlalchemy/engine/base.py", line 1466, in _handle_dbapi_exception
    util.raise_from_cause(sqlalchemy_exception, exc_info)
  File "/usr/local/lib/python3.6/site-packages/sqlalchemy/util/compat.py", line 383, in raise_from_cause
    reraise(type(exception), exception, tb=exc_tb, cause=cause)
  File "/usr/local/lib/python3.6/site-packages/sqlalchemy/util/compat.py", line 128, in reraise
    raise value.with_traceback(tb)
  File "/usr/local/lib/python3.6/site-packages/sqlalchemy/engine/base.py", line 1244, in _execute_context
    cursor, statement, parameters, context
  File "/usr/local/lib/python3.6/site-packages/sqlalchemy/engine/default.py", line 552, in do_execute
    cursor.execute(statement, parameters)
  File "/usr/local/lib64/python3.6/site-packages/elasticapm/instrumentation/packages/dbapi2.py", line 209, in execute
    return self._trace_sql(self.__wrapped__.execute, sql, params)
  File "/usr/local/lib64/python3.6/site-packages/elasticapm/instrumentation/packages/dbapi2.py", line 238, in _trace_sql
    return method(sql, params)
  File "/usr/local/lib/python3.6/site-packages/pymysql/cursors.py", line 170, in execute
    result = self._query(query)
  File "/usr/local/lib/python3.6/site-packages/pymysql/cursors.py", line 328, in _query
    conn.query(q)
  File "/usr/local/lib/python3.6/site-packages/pymysql/connections.py", line 516, in query
    self._affected_rows = self._read_query_result(unbuffered=unbuffered)
  File "/usr/local/lib/python3.6/site-packages/pymysql/connections.py", line 727, in _read_query_result
    result.read()
  File "/usr/local/lib/python3.6/site-packages/pymysql/connections.py", line 1066, in read
    first_packet = self.connection._read_packet()
  File "/usr/local/lib/python3.6/site-packages/pymysql/connections.py", line 683, in _read_packet
    packet.check_error()
  File "/usr/local/lib/python3.6/site-packages/pymysql/protocol.py", line 220, in check_error
    err.raise_mysql_exception(self._data)
  File "/usr/local/lib/python3.6/site-packages/pymysql/err.py", line 109, in raise_mysql_exception
    raise errorclass(errno, errval)
sqlalchemy.exc.InternalError: (pymysql.err.InternalError) (1054, "Unknown column 'et_accounts.mobile' in 'field list'")
[SQL: SELECT et_accounts.id AS et_accounts_id, et_accounts.name AS et_accounts_name, et_accounts.password AS et_accounts_password, et_accounts.mobile AS et_accounts_mobile, et_accounts.role_id AS et_accounts_role_id, et_accounts.status AS et_accounts_status, et_accounts.add_time AS et_accounts_add_time, et_accounts.last_login AS et_accounts_last_login, et_accounts.ip AS et_accounts_ip 
FROM et_accounts 
WHERE et_accounts.name = %(name_1)s AND et_accounts.password = %(password_1)s 
 LIMIT %(param_1)s]
[parameters: {'name_1': 'admin', 'password_1': '54d50ca4a93ea84ad048a2aba899a9d9', 'param_1': 1}]
(Background on this error at: http://sqlalche.me/e/2j85)
[2020-05-07 11:00:07 +0800] [2675] [ERROR] Error handling request /account/login
Traceback (most recent call last):
  File "/usr/local/lib/python3.6/site-packages/sqlalchemy/engine/base.py", line 1244, in _execute_context
    cursor, statement, parameters, context
  File "/usr/local/lib/python3.6/site-packages/sqlalchemy/engine/default.py", line 552, in do_execute
    cursor.execute(statement, parameters)
  File "/usr/local/lib64/python3.6/site-packages/elasticapm/instrumentation/packages/dbapi2.py", line 209, in execute
    return self._trace_sql(self.__wrapped__.execute, sql, params)
  File "/usr/local/lib64/python3.6/site-packages/elasticapm/instrumentation/packages/dbapi2.py", line 238, in _trace_sql
    return method(sql, params)
  File "/usr/local/lib/python3.6/site-packages/pymysql/cursors.py", line 170, in execute
    result = self._query(query)
  File "/usr/local/lib/python3.6/site-packages/pymysql/cursors.py", line 328, in _query
    conn.query(q)
  File "/usr/local/lib/python3.6/site-packages/pymysql/connections.py", line 516, in query
    self._affected_rows = self._read_query_result(unbuffered=unbuffered)
  File "/usr/local/lib/python3.6/site-packages/pymysql/connections.py", line 727, in _read_query_result
    result.read()
  File "/usr/local/lib/python3.6/site-packages/pymysql/connections.py", line 1066, in read
    first_packet = self.connection._read_packet()
  File "/usr/local/lib/python3.6/site-packages/pymysql/connections.py", line 683, in _read_packet
    packet.check_error()
  File "/usr/local/lib/python3.6/site-packages/pymysql/protocol.py", line 220, in check_error
    err.raise_mysql_exception(self._data)
  File "/usr/local/lib/python3.6/site-packages/pymysql/err.py", line 109, in raise_mysql_exception
    raise errorclass(errno, errval)
pymysql.err.InternalError: (1054, "Unknown column 'et_accounts.mobile' in 'field list'")

The above exception was the direct cause of the following exception:

Traceback (most recent call last):
  File "/usr/local/lib/python3.6/site-packages/gunicorn/workers/base_async.py", line 55, in handle
    self.handle_request(listener_name, req, client, addr)
  File "/usr/local/lib/python3.6/site-packages/gunicorn/workers/base_async.py", line 106, in handle_request
    respiter = self.wsgi(environ, resp.start_response)
  File "/usr/local/lib/python3.6/site-packages/flask/app.py", line 2463, in __call__
    return self.wsgi_app(environ, start_response)
  File "/usr/local/lib/python3.6/site-packages/flask/app.py", line 2449, in wsgi_app
    response = self.handle_exception(e)
  File "/usr/local/lib64/python3.6/site-packages/flask_cors/extension.py", line 161, in wrapped_function
    return cors_after_request(app.make_response(f(*args, **kwargs)))
  File "/usr/local/lib/python3.6/site-packages/flask/app.py", line 1866, in handle_exception
    reraise(exc_type, exc_value, tb)
  File "/usr/local/lib/python3.6/site-packages/flask/_compat.py", line 39, in reraise
    raise value
  File "/usr/local/lib/python3.6/site-packages/flask/app.py", line 2446, in wsgi_app
    response = self.full_dispatch_request()
  File "/usr/local/lib/python3.6/site-packages/flask/app.py", line 1951, in full_dispatch_request
    rv = self.handle_user_exception(e)
  File "/usr/local/lib64/python3.6/site-packages/flask_cors/extension.py", line 161, in wrapped_function
    return cors_after_request(app.make_response(f(*args, **kwargs)))
  File "/usr/local/lib/python3.6/site-packages/flask/app.py", line 1820, in handle_user_exception
    reraise(exc_type, exc_value, tb)
  File "/usr/local/lib/python3.6/site-packages/flask/_compat.py", line 39, in reraise
    raise value
  File "/usr/local/lib/python3.6/site-packages/flask/app.py", line 1949, in full_dispatch_request
    rv = self.dispatch_request()
  File "/usr/local/lib/python3.6/site-packages/flask/app.py", line 1935, in dispatch_request
    return self.view_functions[rule.endpoint](**req.view_args)
  File "/home/et/backend_server/app/utils/util.py", line 110, in wrapper
    rv = f(*args, **kwargs)
  File "/home/et/backend_server/app/api/account_service.py", line 120, in handle_login
    EtAccount.password==password_hash).first()
  File "/usr/local/lib/python3.6/site-packages/sqlalchemy/orm/query.py", line 3215, in first
    ret = list(self[0:1])
  File "/usr/local/lib/python3.6/site-packages/sqlalchemy/orm/query.py", line 3007, in __getitem__
    return list(res)
  File "/usr/local/lib/python3.6/site-packages/sqlalchemy/orm/query.py", line 3317, in __iter__
    return self._execute_and_instances(context)
  File "/usr/local/lib/python3.6/site-packages/sqlalchemy/orm/query.py", line 3342, in _execute_and_instances
    result = conn.execute(querycontext.statement, self._params)
  File "/usr/local/lib/python3.6/site-packages/sqlalchemy/engine/base.py", line 988, in execute
    return meth(self, multiparams, params)
  File "/usr/local/lib/python3.6/site-packages/sqlalchemy/sql/elements.py", line 287, in _execute_on_connection
    return connection._execute_clauseelement(self, multiparams, params)
  File "/usr/local/lib/python3.6/site-packages/sqlalchemy/engine/base.py", line 1107, in _execute_clauseelement
    distilled_params,
  File "/usr/local/lib/python3.6/site-packages/sqlalchemy/engine/base.py", line 1248, in _execute_context
    e, statement, parameters, cursor, context
  File "/usr/local/lib/python3.6/site-packages/sqlalchemy/engine/base.py", line 1466, in _handle_dbapi_exception
    util.raise_from_cause(sqlalchemy_exception, exc_info)
  File "/usr/local/lib/python3.6/site-packages/sqlalchemy/util/compat.py", line 383, in raise_from_cause
    reraise(type(exception), exception, tb=exc_tb, cause=cause)
  File "/usr/local/lib/python3.6/site-packages/sqlalchemy/util/compat.py", line 128, in reraise
    raise value.with_traceback(tb)
  File "/usr/local/lib/python3.6/site-packages/sqlalchemy/engine/base.py", line 1244, in _execute_context
    cursor, statement, parameters, context
  File "/usr/local/lib/python3.6/site-packages/sqlalchemy/engine/default.py", line 552, in do_execute
    cursor.execute(statement, parameters)
  File "/usr/local/lib64/python3.6/site-packages/elasticapm/instrumentation/packages/dbapi2.py", line 209, in execute
    return self._trace_sql(self.__wrapped__.execute, sql, params)
  File "/usr/local/lib64/python3.6/site-packages/elasticapm/instrumentation/packages/dbapi2.py", line 238, in _trace_sql
    return method(sql, params)
  File "/usr/local/lib/python3.6/site-packages/pymysql/cursors.py", line 170, in execute
    result = self._query(query)
  File "/usr/local/lib/python3.6/site-packages/pymysql/cursors.py", line 328, in _query
    conn.query(q)
  File "/usr/local/lib/python3.6/site-packages/pymysql/connections.py", line 516, in query
    self._affected_rows = self._read_query_result(unbuffered=unbuffered)
  File "/usr/local/lib/python3.6/site-packages/pymysql/connections.py", line 727, in _read_query_result
    result.read()
  File "/usr/local/lib/python3.6/site-packages/pymysql/connections.py", line 1066, in read
    first_packet = self.connection._read_packet()
  File "/usr/local/lib/python3.6/site-packages/pymysql/connections.py", line 683, in _read_packet
    packet.check_error()
  File "/usr/local/lib/python3.6/site-packages/pymysql/protocol.py", line 220, in check_error
    err.raise_mysql_exception(self._data)
  File "/usr/local/lib/python3.6/site-packages/pymysql/err.py", line 109, in raise_mysql_exception
    raise errorclass(errno, errval)
sqlalchemy.exc.InternalError: (pymysql.err.InternalError) (1054, "Unknown column 'et_accounts.mobile' in 'field list'")
[SQL: SELECT et_accounts.id AS et_accounts_id, et_accounts.name AS et_accounts_name, et_accounts.password AS et_accounts_password, et_accounts.mobile AS et_accounts_mobile, et_accounts.role_id AS et_accounts_role_id, et_accounts.status AS et_accounts_status, et_accounts.add_time AS et_accounts_add_time, et_accounts.last_login AS et_accounts_last_login, et_accounts.ip AS et_accounts_ip 
FROM et_accounts 
WHERE et_accounts.name = %(name_1)s AND et_accounts.password = %(password_1)s 
 LIMIT %(param_1)s]
[parameters: {'name_1': 'admin', 'password_1': '54d50ca4a93ea84ad048a2aba899a9d9', 'param_1': 1}]
(Background on this error at: http://sqlalche.me/e/2j85)
[2020-05-07 11:00:11 +0800] [2675] [INFO] Worker reloading: /home/et/backend_server/app/api/oem_service.py modified
[2020-05-07 11:00:11 +0800] [2675] [INFO] Worker exiting (pid: 2675)
[2020-05-07 11:00:11 +0800] [2676] [INFO] Worker reloading: /home/et/backend_server/app/api/oem_service.py modified
[2020-05-07 11:00:11 +0800] [2676] [INFO] Worker exiting (pid: 2676)
[2020-05-07 11:00:11 +0800] [4313] [INFO] Booting worker with pid: 4313
[2020-05-07 11:00:11 +0800] [4314] [INFO] Booting worker with pid: 4314
[2020-05-07 11:02:31 +0800] [4313] [ERROR] Error handling request /account/login
Traceback (most recent call last):
  File "/usr/local/lib/python3.6/site-packages/sqlalchemy/engine/base.py", line 1244, in _execute_context
    cursor, statement, parameters, context
  File "/usr/local/lib/python3.6/site-packages/sqlalchemy/engine/default.py", line 552, in do_execute
    cursor.execute(statement, parameters)
  File "/usr/local/lib64/python3.6/site-packages/elasticapm/instrumentation/packages/dbapi2.py", line 209, in execute
    return self._trace_sql(self.__wrapped__.execute, sql, params)
  File "/usr/local/lib64/python3.6/site-packages/elasticapm/instrumentation/packages/dbapi2.py", line 238, in _trace_sql
    return method(sql, params)
  File "/usr/local/lib/python3.6/site-packages/pymysql/cursors.py", line 170, in execute
    result = self._query(query)
  File "/usr/local/lib/python3.6/site-packages/pymysql/cursors.py", line 328, in _query
    conn.query(q)
  File "/usr/local/lib/python3.6/site-packages/pymysql/connections.py", line 516, in query
    self._affected_rows = self._read_query_result(unbuffered=unbuffered)
  File "/usr/local/lib/python3.6/site-packages/pymysql/connections.py", line 727, in _read_query_result
    result.read()
  File "/usr/local/lib/python3.6/site-packages/pymysql/connections.py", line 1066, in read
    first_packet = self.connection._read_packet()
  File "/usr/local/lib/python3.6/site-packages/pymysql/connections.py", line 683, in _read_packet
    packet.check_error()
  File "/usr/local/lib/python3.6/site-packages/pymysql/protocol.py", line 220, in check_error
    err.raise_mysql_exception(self._data)
  File "/usr/local/lib/python3.6/site-packages/pymysql/err.py", line 109, in raise_mysql_exception
    raise errorclass(errno, errval)
pymysql.err.InternalError: (1054, "Unknown column 'et_accounts.mobile' in 'field list'")

The above exception was the direct cause of the following exception:

Traceback (most recent call last):
  File "/usr/local/lib/python3.6/site-packages/gunicorn/workers/base_async.py", line 55, in handle
    self.handle_request(listener_name, req, client, addr)
  File "/usr/local/lib/python3.6/site-packages/gunicorn/workers/base_async.py", line 106, in handle_request
    respiter = self.wsgi(environ, resp.start_response)
  File "/usr/local/lib/python3.6/site-packages/flask/app.py", line 2463, in __call__
    return self.wsgi_app(environ, start_response)
  File "/usr/local/lib/python3.6/site-packages/flask/app.py", line 2449, in wsgi_app
    response = self.handle_exception(e)
  File "/usr/local/lib64/python3.6/site-packages/flask_cors/extension.py", line 161, in wrapped_function
    return cors_after_request(app.make_response(f(*args, **kwargs)))
  File "/usr/local/lib/python3.6/site-packages/flask/app.py", line 1866, in handle_exception
    reraise(exc_type, exc_value, tb)
  File "/usr/local/lib/python3.6/site-packages/flask/_compat.py", line 39, in reraise
    raise value
  File "/usr/local/lib/python3.6/site-packages/flask/app.py", line 2446, in wsgi_app
    response = self.full_dispatch_request()
  File "/usr/local/lib/python3.6/site-packages/flask/app.py", line 1951, in full_dispatch_request
    rv = self.handle_user_exception(e)
  File "/usr/local/lib64/python3.6/site-packages/flask_cors/extension.py", line 161, in wrapped_function
    return cors_after_request(app.make_response(f(*args, **kwargs)))
  File "/usr/local/lib/python3.6/site-packages/flask/app.py", line 1820, in handle_user_exception
    reraise(exc_type, exc_value, tb)
  File "/usr/local/lib/python3.6/site-packages/flask/_compat.py", line 39, in reraise
    raise value
  File "/usr/local/lib/python3.6/site-packages/flask/app.py", line 1949, in full_dispatch_request
    rv = self.dispatch_request()
  File "/usr/local/lib/python3.6/site-packages/flask/app.py", line 1935, in dispatch_request
    return self.view_functions[rule.endpoint](**req.view_args)
  File "/home/et/backend_server/app/utils/util.py", line 110, in wrapper
    rv = f(*args, **kwargs)
  File "/home/et/backend_server/app/api/account_service.py", line 120, in handle_login
    EtAccount.password==password_hash).first()
  File "/usr/local/lib/python3.6/site-packages/sqlalchemy/orm/query.py", line 3215, in first
    ret = list(self[0:1])
  File "/usr/local/lib/python3.6/site-packages/sqlalchemy/orm/query.py", line 3007, in __getitem__
    return list(res)
  File "/usr/local/lib/python3.6/site-packages/sqlalchemy/orm/query.py", line 3317, in __iter__
    return self._execute_and_instances(context)
  File "/usr/local/lib/python3.6/site-packages/sqlalchemy/orm/query.py", line 3342, in _execute_and_instances
    result = conn.execute(querycontext.statement, self._params)
  File "/usr/local/lib/python3.6/site-packages/sqlalchemy/engine/base.py", line 988, in execute
    return meth(self, multiparams, params)
  File "/usr/local/lib/python3.6/site-packages/sqlalchemy/sql/elements.py", line 287, in _execute_on_connection
    return connection._execute_clauseelement(self, multiparams, params)
  File "/usr/local/lib/python3.6/site-packages/sqlalchemy/engine/base.py", line 1107, in _execute_clauseelement
    distilled_params,
  File "/usr/local/lib/python3.6/site-packages/sqlalchemy/engine/base.py", line 1248, in _execute_context
    e, statement, parameters, cursor, context
  File "/usr/local/lib/python3.6/site-packages/sqlalchemy/engine/base.py", line 1466, in _handle_dbapi_exception
    util.raise_from_cause(sqlalchemy_exception, exc_info)
  File "/usr/local/lib/python3.6/site-packages/sqlalchemy/util/compat.py", line 383, in raise_from_cause
    reraise(type(exception), exception, tb=exc_tb, cause=cause)
  File "/usr/local/lib/python3.6/site-packages/sqlalchemy/util/compat.py", line 128, in reraise
    raise value.with_traceback(tb)
  File "/usr/local/lib/python3.6/site-packages/sqlalchemy/engine/base.py", line 1244, in _execute_context
    cursor, statement, parameters, context
  File "/usr/local/lib/python3.6/site-packages/sqlalchemy/engine/default.py", line 552, in do_execute
    cursor.execute(statement, parameters)
  File "/usr/local/lib64/python3.6/site-packages/elasticapm/instrumentation/packages/dbapi2.py", line 209, in execute
    return self._trace_sql(self.__wrapped__.execute, sql, params)
  File "/usr/local/lib64/python3.6/site-packages/elasticapm/instrumentation/packages/dbapi2.py", line 238, in _trace_sql
    return method(sql, params)
  File "/usr/local/lib/python3.6/site-packages/pymysql/cursors.py", line 170, in execute
    result = self._query(query)
  File "/usr/local/lib/python3.6/site-packages/pymysql/cursors.py", line 328, in _query
    conn.query(q)
  File "/usr/local/lib/python3.6/site-packages/pymysql/connections.py", line 516, in query
    self._affected_rows = self._read_query_result(unbuffered=unbuffered)
  File "/usr/local/lib/python3.6/site-packages/pymysql/connections.py", line 727, in _read_query_result
    result.read()
  File "/usr/local/lib/python3.6/site-packages/pymysql/connections.py", line 1066, in read
    first_packet = self.connection._read_packet()
  File "/usr/local/lib/python3.6/site-packages/pymysql/connections.py", line 683, in _read_packet
    packet.check_error()
  File "/usr/local/lib/python3.6/site-packages/pymysql/protocol.py", line 220, in check_error
    err.raise_mysql_exception(self._data)
  File "/usr/local/lib/python3.6/site-packages/pymysql/err.py", line 109, in raise_mysql_exception
    raise errorclass(errno, errval)
sqlalchemy.exc.InternalError: (pymysql.err.InternalError) (1054, "Unknown column 'et_accounts.mobile' in 'field list'")
[SQL: SELECT et_accounts.id AS et_accounts_id, et_accounts.name AS et_accounts_name, et_accounts.password AS et_accounts_password, et_accounts.mobile AS et_accounts_mobile, et_accounts.role_id AS et_accounts_role_id, et_accounts.status AS et_accounts_status, et_accounts.add_time AS et_accounts_add_time, et_accounts.last_login AS et_accounts_last_login, et_accounts.ip AS et_accounts_ip 
FROM et_accounts 
WHERE et_accounts.name = %(name_1)s AND et_accounts.password = %(password_1)s 
 LIMIT %(param_1)s]
[parameters: {'name_1': 'admin', 'password_1': '54d50ca4a93ea84ad048a2aba899a9d9', 'param_1': 1}]
(Background on this error at: http://sqlalche.me/e/2j85)
[2020-05-07 11:03:33 +0800] [4313] [ERROR] Error handling request /account/login
Traceback (most recent call last):
  File "/usr/local/lib/python3.6/site-packages/sqlalchemy/engine/base.py", line 1244, in _execute_context
    cursor, statement, parameters, context
  File "/usr/local/lib/python3.6/site-packages/sqlalchemy/engine/default.py", line 552, in do_execute
    cursor.execute(statement, parameters)
  File "/usr/local/lib64/python3.6/site-packages/elasticapm/instrumentation/packages/dbapi2.py", line 209, in execute
    return self._trace_sql(self.__wrapped__.execute, sql, params)
  File "/usr/local/lib64/python3.6/site-packages/elasticapm/instrumentation/packages/dbapi2.py", line 238, in _trace_sql
    return method(sql, params)
  File "/usr/local/lib/python3.6/site-packages/pymysql/cursors.py", line 170, in execute
    result = self._query(query)
  File "/usr/local/lib/python3.6/site-packages/pymysql/cursors.py", line 328, in _query
    conn.query(q)
  File "/usr/local/lib/python3.6/site-packages/pymysql/connections.py", line 516, in query
    self._affected_rows = self._read_query_result(unbuffered=unbuffered)
  File "/usr/local/lib/python3.6/site-packages/pymysql/connections.py", line 727, in _read_query_result
    result.read()
  File "/usr/local/lib/python3.6/site-packages/pymysql/connections.py", line 1066, in read
    first_packet = self.connection._read_packet()
  File "/usr/local/lib/python3.6/site-packages/pymysql/connections.py", line 683, in _read_packet
    packet.check_error()
  File "/usr/local/lib/python3.6/site-packages/pymysql/protocol.py", line 220, in check_error
    err.raise_mysql_exception(self._data)
  File "/usr/local/lib/python3.6/site-packages/pymysql/err.py", line 109, in raise_mysql_exception
    raise errorclass(errno, errval)
pymysql.err.InternalError: (1054, "Unknown column 'et_accounts.mobile' in 'field list'")

The above exception was the direct cause of the following exception:

Traceback (most recent call last):
  File "/usr/local/lib/python3.6/site-packages/gunicorn/workers/base_async.py", line 55, in handle
    self.handle_request(listener_name, req, client, addr)
  File "/usr/local/lib/python3.6/site-packages/gunicorn/workers/base_async.py", line 106, in handle_request
    respiter = self.wsgi(environ, resp.start_response)
  File "/usr/local/lib/python3.6/site-packages/flask/app.py", line 2463, in __call__
    return self.wsgi_app(environ, start_response)
  File "/usr/local/lib/python3.6/site-packages/flask/app.py", line 2449, in wsgi_app
    response = self.handle_exception(e)
  File "/usr/local/lib64/python3.6/site-packages/flask_cors/extension.py", line 161, in wrapped_function
    return cors_after_request(app.make_response(f(*args, **kwargs)))
  File "/usr/local/lib/python3.6/site-packages/flask/app.py", line 1866, in handle_exception
    reraise(exc_type, exc_value, tb)
  File "/usr/local/lib/python3.6/site-packages/flask/_compat.py", line 39, in reraise
    raise value
  File "/usr/local/lib/python3.6/site-packages/flask/app.py", line 2446, in wsgi_app
    response = self.full_dispatch_request()
  File "/usr/local/lib/python3.6/site-packages/flask/app.py", line 1951, in full_dispatch_request
    rv = self.handle_user_exception(e)
  File "/usr/local/lib64/python3.6/site-packages/flask_cors/extension.py", line 161, in wrapped_function
    return cors_after_request(app.make_response(f(*args, **kwargs)))
  File "/usr/local/lib/python3.6/site-packages/flask/app.py", line 1820, in handle_user_exception
    reraise(exc_type, exc_value, tb)
  File "/usr/local/lib/python3.6/site-packages/flask/_compat.py", line 39, in reraise
    raise value
  File "/usr/local/lib/python3.6/site-packages/flask/app.py", line 1949, in full_dispatch_request
    rv = self.dispatch_request()
  File "/usr/local/lib/python3.6/site-packages/flask/app.py", line 1935, in dispatch_request
    return self.view_functions[rule.endpoint](**req.view_args)
  File "/home/et/backend_server/app/utils/util.py", line 110, in wrapper
    rv = f(*args, **kwargs)
  File "/home/et/backend_server/app/api/account_service.py", line 120, in handle_login
    EtAccount.password==password_hash).first()
  File "/usr/local/lib/python3.6/site-packages/sqlalchemy/orm/query.py", line 3215, in first
    ret = list(self[0:1])
  File "/usr/local/lib/python3.6/site-packages/sqlalchemy/orm/query.py", line 3007, in __getitem__
    return list(res)
  File "/usr/local/lib/python3.6/site-packages/sqlalchemy/orm/query.py", line 3317, in __iter__
    return self._execute_and_instances(context)
  File "/usr/local/lib/python3.6/site-packages/sqlalchemy/orm/query.py", line 3342, in _execute_and_instances
    result = conn.execute(querycontext.statement, self._params)
  File "/usr/local/lib/python3.6/site-packages/sqlalchemy/engine/base.py", line 988, in execute
    return meth(self, multiparams, params)
  File "/usr/local/lib/python3.6/site-packages/sqlalchemy/sql/elements.py", line 287, in _execute_on_connection
    return connection._execute_clauseelement(self, multiparams, params)
  File "/usr/local/lib/python3.6/site-packages/sqlalchemy/engine/base.py", line 1107, in _execute_clauseelement
    distilled_params,
  File "/usr/local/lib/python3.6/site-packages/sqlalchemy/engine/base.py", line 1248, in _execute_context
    e, statement, parameters, cursor, context
  File "/usr/local/lib/python3.6/site-packages/sqlalchemy/engine/base.py", line 1466, in _handle_dbapi_exception
    util.raise_from_cause(sqlalchemy_exception, exc_info)
  File "/usr/local/lib/python3.6/site-packages/sqlalchemy/util/compat.py", line 383, in raise_from_cause
    reraise(type(exception), exception, tb=exc_tb, cause=cause)
  File "/usr/local/lib/python3.6/site-packages/sqlalchemy/util/compat.py", line 128, in reraise
    raise value.with_traceback(tb)
  File "/usr/local/lib/python3.6/site-packages/sqlalchemy/engine/base.py", line 1244, in _execute_context
    cursor, statement, parameters, context
  File "/usr/local/lib/python3.6/site-packages/sqlalchemy/engine/default.py", line 552, in do_execute
    cursor.execute(statement, parameters)
  File "/usr/local/lib64/python3.6/site-packages/elasticapm/instrumentation/packages/dbapi2.py", line 209, in execute
    return self._trace_sql(self.__wrapped__.execute, sql, params)
  File "/usr/local/lib64/python3.6/site-packages/elasticapm/instrumentation/packages/dbapi2.py", line 238, in _trace_sql
    return method(sql, params)
  File "/usr/local/lib/python3.6/site-packages/pymysql/cursors.py", line 170, in execute
    result = self._query(query)
  File "/usr/local/lib/python3.6/site-packages/pymysql/cursors.py", line 328, in _query
    conn.query(q)
  File "/usr/local/lib/python3.6/site-packages/pymysql/connections.py", line 516, in query
    self._affected_rows = self._read_query_result(unbuffered=unbuffered)
  File "/usr/local/lib/python3.6/site-packages/pymysql/connections.py", line 727, in _read_query_result
    result.read()
  File "/usr/local/lib/python3.6/site-packages/pymysql/connections.py", line 1066, in read
    first_packet = self.connection._read_packet()
  File "/usr/local/lib/python3.6/site-packages/pymysql/connections.py", line 683, in _read_packet
    packet.check_error()
  File "/usr/local/lib/python3.6/site-packages/pymysql/protocol.py", line 220, in check_error
    err.raise_mysql_exception(self._data)
  File "/usr/local/lib/python3.6/site-packages/pymysql/err.py", line 109, in raise_mysql_exception
    raise errorclass(errno, errval)
sqlalchemy.exc.InternalError: (pymysql.err.InternalError) (1054, "Unknown column 'et_accounts.mobile' in 'field list'")
[SQL: SELECT et_accounts.id AS et_accounts_id, et_accounts.name AS et_accounts_name, et_accounts.password AS et_accounts_password, et_accounts.mobile AS et_accounts_mobile, et_accounts.role_id AS et_accounts_role_id, et_accounts.status AS et_accounts_status, et_accounts.add_time AS et_accounts_add_time, et_accounts.last_login AS et_accounts_last_login, et_accounts.ip AS et_accounts_ip 
FROM et_accounts 
WHERE et_accounts.name = %(name_1)s AND et_accounts.password = %(password_1)s 
 LIMIT %(param_1)s]
[parameters: {'name_1': 'admin', 'password_1': '54d50ca4a93ea84ad048a2aba899a9d9', 'param_1': 1}]
(Background on this error at: http://sqlalche.me/e/2j85)
[2020-05-07 11:05:31 +0800] [4313] [INFO] Worker reloading: /home/et/backend_server/app/models/accounts.py modified
[2020-05-07 11:05:31 +0800] [4313] [INFO] Worker exiting (pid: 4313)
[2020-05-07 11:05:31 +0800] [4314] [INFO] Worker reloading: /home/et/backend_server/app/models/accounts.py modified
[2020-05-07 11:05:31 +0800] [4314] [INFO] Worker exiting (pid: 4314)
[2020-05-07 11:05:31 +0800] [6561] [INFO] Booting worker with pid: 6561
[2020-05-07 11:05:31 +0800] [6562] [INFO] Booting worker with pid: 6562
[2020-05-07 11:14:45 +0800] [6561] [INFO] Worker reloading: /home/et/backend_server/app/models/accounts.py modified
[2020-05-07 11:14:45 +0800] [6562] [INFO] Worker reloading: /home/et/backend_server/app/models/accounts.py modified
[2020-05-07 11:14:45 +0800] [6561] [INFO] Worker exiting (pid: 6561)
[2020-05-07 11:14:45 +0800] [6562] [INFO] Worker exiting (pid: 6562)
[2020-05-07 11:14:45 +0800] [10349] [INFO] Booting worker with pid: 10349
[2020-05-07 11:14:46 +0800] [10351] [INFO] Booting worker with pid: 10351
[2020-05-07 11:16:12 +0800] [10349] [INFO] Worker reloading: /home/et/backend_server/app/factory.py modified
[2020-05-07 11:16:12 +0800] [10349] [INFO] Worker exiting (pid: 10349)
[2020-05-07 11:16:12 +0800] [10351] [INFO] Worker reloading: /home/et/backend_server/app/factory.py modified
[2020-05-07 11:16:12 +0800] [10351] [INFO] Worker exiting (pid: 10351)
[2020-05-07 11:16:12 +0800] [10969] [INFO] Booting worker with pid: 10969
[2020-05-07 11:16:12 +0800] [10970] [INFO] Booting worker with pid: 10970
[2020-05-07 11:17:05 +0800] [10969] [INFO] Worker reloading: /home/et/backend_server/app/factory.py modified
[2020-05-07 11:17:05 +0800] [10969] [INFO] Worker exiting (pid: 10969)
[2020-05-07 11:17:05 +0800] [10970] [INFO] Worker reloading: /home/et/backend_server/app/factory.py modified
[2020-05-07 11:17:05 +0800] [10970] [INFO] Worker exiting (pid: 10970)
[2020-05-07 11:17:05 +0800] [11326] [INFO] Booting worker with pid: 11326
[2020-05-07 11:17:05 +0800] [11327] [INFO] Booting worker with pid: 11327
[2020-05-07 11:17:22 +0800] [11326] [INFO] Worker reloading: /home/et/backend_server/app/factory.py modified
[2020-05-07 11:17:22 +0800] [11326] [INFO] Worker exiting (pid: 11326)
[2020-05-07 11:17:22 +0800] [11327] [INFO] Worker reloading: /home/et/backend_server/app/factory.py modified
[2020-05-07 11:17:22 +0800] [11327] [INFO] Worker exiting (pid: 11327)
[2020-05-07 11:17:22 +0800] [11458] [INFO] Booting worker with pid: 11458
[2020-05-07 11:17:22 +0800] [11459] [INFO] Booting worker with pid: 11459
[2020-05-07 11:17:23 +0800] [11458] [ERROR] Exception in worker process
Traceback (most recent call last):
  File "/usr/local/lib/python3.6/site-packages/gunicorn/arbiter.py", line 583, in spawn_worker
    worker.init_process()
  File "/usr/local/lib/python3.6/site-packages/gunicorn/workers/geventlet.py", line 99, in init_process
    super().init_process()
  File "/usr/local/lib/python3.6/site-packages/gunicorn/workers/base.py", line 119, in init_process
    self.load_wsgi()
  File "/usr/local/lib/python3.6/site-packages/gunicorn/workers/base.py", line 144, in load_wsgi
    self.wsgi = self.app.wsgi()
  File "/usr/local/lib/python3.6/site-packages/gunicorn/app/base.py", line 67, in wsgi
    self.callable = self.load()
  File "/usr/local/lib/python3.6/site-packages/gunicorn/app/wsgiapp.py", line 49, in load
    return self.load_wsgiapp()
  File "/usr/local/lib/python3.6/site-packages/gunicorn/app/wsgiapp.py", line 39, in load_wsgiapp
    return util.import_app(self.app_uri)
  File "/usr/local/lib/python3.6/site-packages/gunicorn/util.py", line 358, in import_app
    mod = importlib.import_module(module)
  File "/usr/lib64/python3.6/importlib/__init__.py", line 126, in import_module
    return _bootstrap._gcd_import(name[level:], package, level)
  File "<frozen importlib._bootstrap>", line 994, in _gcd_import
  File "<frozen importlib._bootstrap>", line 971, in _find_and_load
  File "<frozen importlib._bootstrap>", line 955, in _find_and_load_unlocked
  File "<frozen importlib._bootstrap>", line 665, in _load_unlocked
  File "<frozen importlib._bootstrap_external>", line 678, in exec_module
  File "<frozen importlib._bootstrap>", line 219, in _call_with_frames_removed
  File "/home/et/backend_server/wsgi_gunicorn.py", line 1, in <module>
    from app.factory import create_app, celery_app
  File "/home/et/backend_server/app/factory.py", line 16, in <module>
    s
NameError: name 's' is not defined
[2020-05-07 11:17:23 +0800] [11458] [INFO] Worker exiting (pid: 11458)
[2020-05-07 11:17:23 +0800] [11459] [ERROR] Exception in worker process
Traceback (most recent call last):
  File "/usr/local/lib/python3.6/site-packages/gunicorn/arbiter.py", line 583, in spawn_worker
    worker.init_process()
  File "/usr/local/lib/python3.6/site-packages/gunicorn/workers/geventlet.py", line 99, in init_process
    super().init_process()
  File "/usr/local/lib/python3.6/site-packages/gunicorn/workers/base.py", line 119, in init_process
    self.load_wsgi()
  File "/usr/local/lib/python3.6/site-packages/gunicorn/workers/base.py", line 144, in load_wsgi
    self.wsgi = self.app.wsgi()
  File "/usr/local/lib/python3.6/site-packages/gunicorn/app/base.py", line 67, in wsgi
    self.callable = self.load()
  File "/usr/local/lib/python3.6/site-packages/gunicorn/app/wsgiapp.py", line 49, in load
    return self.load_wsgiapp()
  File "/usr/local/lib/python3.6/site-packages/gunicorn/app/wsgiapp.py", line 39, in load_wsgiapp
    return util.import_app(self.app_uri)
  File "/usr/local/lib/python3.6/site-packages/gunicorn/util.py", line 358, in import_app
    mod = importlib.import_module(module)
  File "/usr/lib64/python3.6/importlib/__init__.py", line 126, in import_module
    return _bootstrap._gcd_import(name[level:], package, level)
  File "<frozen importlib._bootstrap>", line 994, in _gcd_import
  File "<frozen importlib._bootstrap>", line 971, in _find_and_load
  File "<frozen importlib._bootstrap>", line 955, in _find_and_load_unlocked
  File "<frozen importlib._bootstrap>", line 665, in _load_unlocked
  File "<frozen importlib._bootstrap_external>", line 678, in exec_module
  File "<frozen importlib._bootstrap>", line 219, in _call_with_frames_removed
  File "/home/et/backend_server/wsgi_gunicorn.py", line 1, in <module>
    from app.factory import create_app, celery_app
  File "/home/et/backend_server/app/factory.py", line 16, in <module>
    s
NameError: name 's' is not defined
[2020-05-07 11:17:23 +0800] [11459] [INFO] Worker exiting (pid: 11459)
[2020-05-07 11:17:23 +0800] [16146] [INFO] Shutting down: Master
[2020-05-07 11:17:23 +0800] [16146] [INFO] Reason: Worker failed to boot.
